Workbook

Sheet ข้อควรรู้ก่อนเริ่ม 
A1: Version | B1: 1.5.1
A2: ข้อควรรู้ก่อนเริ่ม
A3: 1. ฟอร์มนำเข้าข้อมูลคะแนนได้ทำการผูกสูตรและล๊อกเซลล์ไว้แล้ว ซึ่งเซลล์ที่ถูกล๊อกไว้จะไม่สามารถกดหรือทำการแก้ไขได้
A4: 2. --รหัสนักเรียน-- ให้กรอกเฉพาะในชีท "คะแนนเก็บ" และต้องตรงกันกับในฐานข้อมูล School Bright จึงจะทำการอัพโหลดได้
A5: 3. ให้แยกไฟล์ออกเป็นแต่ล่ะวิชาและแต่ล่ะห้อง ( 1 ไฟล์ ต่อ 1 วิชา ต่อ 1 ห้อง)
A6: 4. สามารถกรอกได้สูงสุดครั้งล่ะ 60 คน ต่อไฟล์
A7: 5. สามารถศึกษาวีดีโอการลงข้อมูลอย่างละเอียดได้จากลิงค์ www.youtube.com

Sheet ตั้งค่าสัดส่วนคะแนน
A1: ชีท --ตั้งค่าสัดส่วนคะแนน-- ให้ตั้งสัดส่วนคะแนนของคะแนนเก็บ คะแนนเก็บหลังกลางภาค กลางภาค ปลายภาค และ %ตัดผ่านของคะแนนเก็บ/ตัวชี้วัด ตามความต้องการ ---ห้ามเว้นว่างไว้---
A2: คะแนนเก็บ | B2: กลางภาค | C2: คะแนนเก็บหลังกลางภาค | D2: ปลายภาค | E2: % ตัดผ่านของคะแนนเก็บ/หน่วยชี้วัดแต่ละจุด
A5: คำอธิบาย
A6: กรณีที่ 1 ไม่แยกคะแนนเก็บก่อนและหลังกลางภาคในระบบ
A7: 1. สมมุติว่าวิชาภาษาไทย มีสัดส่วนคะแนนเป็น คะแนนเก็บ 50 คะแนนสอบกลางภาค 20 และคะแนนสอบปลายภาค 30
A8: ให้ตั้งค่าดังนี้ คะแนนเก็บ 50 คะแนนเก็บหลังกลางภาค 0 คะแนนสอบกลางภาค 20 และคะแนนสอบปลายภาค 30
A9: กรณีที่ 2 แยกคะแนนเก็บก่อนและหลังกลางภาคในระบบ
A10: 2. สมมุติว่าวิชาภาษาไทย มีสัดส่วนคะแนนเป็น คะแนนเก็บ 30 คะแนนเก็บหลังกลางภาค 20 คะแนนสอบกลางภาค 20 และคะแนนสอบปลายภาค 30
A11: ให้ตั้งค่าดังนี้ คะแนนเก็บ 30 คะแนนเก็บหลังกลางภาค 20 คะแนนสอบกลางภาค 20 และคะแนนสอบปลายภาค 30
A12: 3. %ตัดผ่านของคะแนนเก็บ/หน่วยชี้วัด หมายถึง คะแนนที่นักเรียนต้องทำได้เป็นอย่างน้อยในส่วนคะแนนเก็บ จึงจะถือว่าผ่าน
A13: เช่น หัวข้อคะแนนที่ 1 เต็ม 10 คะแนน นักเรียนต้องได้ 6 คะแนน ให้ตั้งเป็น 60

Sheet คะแนนเก็บ
A1: ชีท --คะแนนเก็บ-- ให้ตั้งชื่อหัวข้อตามความต้องการและกรอกคะแนนเต็มของแต่ล่ะหน่วย ---ช่องใดไม่ใช้งานให้เว้นว่างไว้---
A2: เลขที่ | B2: รหัสนักเรียน | C2: ชื่อหัวข้อ | D2: คะแนนเก็บ/ตัวชี้วัด | X2: รวม
D3: ตัวอย่าง | E3: 2 | F3: 3 | G3: 4 | H3: 5 | I3: 6 | J3: 7 | K3: 8 | L3: 9 | M3: 10 | N3: 11 | O3: 12 | P3: 13 | Q3: 14 | R3: 15 | S3: 16 | T3: 17 | U3: 18 | V3: 19 | W3: 20
C4: คะแนนเต็ม | D4: 10 | X4: =IF(AND(ISBLANK(D4)=TRUE,ISBLANK(E4)=TRUE,ISBLANK(F4)=TRUE,ISBLANK(G4)=TRUE,ISBLANK(H4)=TRUE,ISBLANK(I4)=TRUE,ISBLANK(J4)=TRUE,ISBLANK(K4)=TRUE,ISBLANK(L4)=TRUE,ISBLANK(M4)=TRUE,ISBLANK(N4)=TRUE,ISBLANK(O4)=TRUE,ISBLANK(P4)=TRUE,ISBLANK(Q4)=TRUE,ISBLANK(R4)=TRUE,ISBLANK(S4)=TRUE,ISBLANK(T4)=TRUE,ISBLANK(U4)=TRUE,ISBLANK(V4)=TRUE,ISBLANK(W4)=TRUE),"",SUM(D4:W4)) -> 10
A5: 1 | B5: 123 | C5: เด็กชายจับจ่าย รักโรงเรียน | D5: 1 | X5: =IF(AND(ISBLANK(D5)=TRUE,ISBLANK(E5)=TRUE,ISBLANK(F5)=TRUE,ISBLANK(G5)=TRUE,ISBLANK(H5)=TRUE,ISBLANK(I5)=TRUE,ISBLANK(J5)=TRUE,ISBLANK(K5)=TRUE,ISBLANK(L5)=TRUE,ISBLANK(M5)=TRUE,ISBLANK(N5)=TRUE,ISBLANK(O5)=TRUE,ISBLANK(P5)=TRUE,ISBLANK(Q5)=TRUE,ISBLANK(R5)=TRUE,ISBLANK(S5)=TRUE,ISBLANK(T5)=TRUE,ISBLANK(U5)=TRUE,ISBLANK(V5)=TRUE,ISBLANK(W5)=TRUE),"",SUM(D5:W5)) -> 1
A6: 2 | B6: 456 | C6: เด็กชายสคูล ไบร์ท | D6: 2 | X6: =IF(AND(ISBLANK(D6)=TRUE,ISBLANK(E6)=TRUE,ISBLANK(F6)=TRUE,ISBLANK(G6)=TRUE,ISBLANK(H6)=TRUE,ISBLANK(I6)=TRUE,ISBLANK(J6)=TRUE,ISBLANK(K6)=TRUE,ISBLANK(L6)=TRUE,ISBLANK(M6)=TRUE,ISBLANK(N6)=TRUE,ISBLANK(O6)=TRUE,ISBLANK(P6)=TRUE,ISBLANK(Q6)=TRUE,ISBLANK(R6)=TRUE,ISBLANK(S6)=TRUE,ISBLANK(T6)=TRUE,ISBLANK(U6)=TRUE,ISBLANK(V6)=TRUE,ISBLANK(W6)=TRUE),"",SUM(D6:W6)) -> 2
A7: 3 | B7: A123 | C7: เด็กหญิงน้ำเพชร ใจดี | D7: 3 | X7: =IF(AND(ISBLANK(D7)=TRUE,ISBLANK(E7)=TRUE,ISBLANK(F7)=TRUE,ISBLANK(G7)=TRUE,ISBLANK(H7)=TRUE,ISBLANK(I7)=TRUE,ISBLANK(J7)=TRUE,ISBLANK(K7)=TRUE,ISBLANK(L7)=TRUE,ISBLANK(M7)=TRUE,ISBLANK(N7)=TRUE,ISBLANK(O7)=TRUE,ISBLANK(P7)=TRUE,ISBLANK(Q7)=TRUE,ISBLANK(R7)=TRUE,ISBLANK(S7)=TRUE,ISBLANK(T7)=TRUE,ISBLANK(U7)=TRUE,ISBLANK(V7)=TRUE,ISBLANK(W7)=TRUE),"",SUM(D7:W7)) -> 3
A8: 4 | X8: =IF(AND(ISBLANK(D8)=TRUE,ISBLANK(E8)=TRUE,ISBLANK(F8)=TRUE,ISBLANK(G8)=TRUE,ISBLANK(H8)=TRUE,ISBLANK(I8)=TRUE,ISBLANK(J8)=TRUE,ISBLANK(K8)=TRUE,ISBLANK(L8)=TRUE,ISBLANK(M8)=TRUE,ISBLANK(N8)=TRUE,ISBLANK(O8)=TRUE,ISBLANK(P8)=TRUE,ISBLANK(Q8)=TRUE,ISBLANK(R8)=TRUE,ISBLANK(S8)=TRUE,ISBLANK(T8)=TRUE,ISBLANK(U8)=TRUE,ISBLANK(V8)=TRUE,ISBLANK(W8)=TRUE),"",SUM(D8:W8))
A9: 5 | X9: =IF(AND(ISBLANK(D9)=TRUE,ISBLANK(E9)=TRUE,ISBLANK(F9)=TRUE,ISBLANK(G9)=TRUE,ISBLANK(H9)=TRUE,ISBLANK(I9)=TRUE,ISBLANK(J9)=TRUE,ISBLANK(K9)=TRUE,ISBLANK(L9)=TRUE,ISBLANK(M9)=TRUE,ISBLANK(N9)=TRUE,ISBLANK(O9)=TRUE,ISBLANK(P9)=TRUE,ISBLANK(Q9)=TRUE,ISBLANK(R9)=TRUE,ISBLANK(S9)=TRUE,ISBLANK(T9)=TRUE,ISBLANK(U9)=TRUE,ISBLANK(V9)=TRUE,ISBLANK(W9)=TRUE),"",SUM(D9:W9))
A10: 6 | X10: =IF(AND(ISBLANK(D10)=TRUE,ISBLANK(E10)=TRUE,ISBLANK(F10)=TRUE,ISBLANK(G10)=TRUE,ISBLANK(H10)=TRUE,ISBLANK(I10)=TRUE,ISBLANK(J10)=TRUE,ISBLANK(K10)=TRUE,ISBLANK(L10)=TRUE,ISBLANK(M10)=TRUE,ISBLANK(N10)=TRUE,ISBLANK(O10)=TRUE,ISBLANK(P10)=TRUE,ISBLANK(Q10)=TRUE,ISBLANK(R10)=TRUE,ISBLANK(S10)=TRUE,ISBLANK(T10)=TRUE,ISBLANK(U10)=TRUE,ISBLANK(V10)=TRUE,ISBLANK(W10)=TRUE),"",SUM(D10:W10))
A11: 7 | X11: =IF(AND(ISBLANK(D11)=TRUE,ISBLANK(E11)=TRUE,ISBLANK(F11)=TRUE,ISBLANK(G11)=TRUE,ISBLANK(H11)=TRUE,ISBLANK(I11)=TRUE,ISBLANK(J11)=TRUE,ISBLANK(K11)=TRUE,ISBLANK(L11)=TRUE,ISBLANK(M11)=TRUE,ISBLANK(N11)=TRUE,ISBLANK(O11)=TRUE,ISBLANK(P11)=TRUE,ISBLANK(Q11)=TRUE,ISBLANK(R11)=TRUE,ISBLANK(S11)=TRUE,ISBLANK(T11)=TRUE,ISBLANK(U11)=TRUE,ISBLANK(V11)=TRUE,ISBLANK(W11)=TRUE),"",SUM(D11:W11))
A12: 8 | X12: =IF(AND(ISBLANK(D12)=TRUE,ISBLANK(E12)=TRUE,ISBLANK(F12)=TRUE,ISBLANK(G12)=TRUE,ISBLANK(H12)=TRUE,ISBLANK(I12)=TRUE,ISBLANK(J12)=TRUE,ISBLANK(K12)=TRUE,ISBLANK(L12)=TRUE,ISBLANK(M12)=TRUE,ISBLANK(N12)=TRUE,ISBLANK(O12)=TRUE,ISBLANK(P12)=TRUE,ISBLANK(Q12)=TRUE,ISBLANK(R12)=TRUE,ISBLANK(S12)=TRUE,ISBLANK(T12)=TRUE,ISBLANK(U12)=TRUE,ISBLANK(V12)=TRUE,ISBLANK(W12)=TRUE),"",SUM(D12:W12))
A13: 9 | X13: =IF(AND(ISBLANK(D13)=TRUE,ISBLANK(E13)=TRUE,ISBLANK(F13)=TRUE,ISBLANK(G13)=TRUE,ISBLANK(H13)=TRUE,ISBLANK(I13)=TRUE,ISBLANK(J13)=TRUE,ISBLANK(K13)=TRUE,ISBLANK(L13)=TRUE,ISBLANK(M13)=TRUE,ISBLANK(N13)=TRUE,ISBLANK(O13)=TRUE,ISBLANK(P13)=TRUE,ISBLANK(Q13)=TRUE,ISBLANK(R13)=TRUE,ISBLANK(S13)=TRUE,ISBLANK(T13)=TRUE,ISBLANK(U13)=TRUE,ISBLANK(V13)=TRUE,ISBLANK(W13)=TRUE),"",SUM(D13:W13))
A14: 10 | X14: =IF(AND(ISBLANK(D14)=TRUE,ISBLANK(E14)=TRUE,ISBLANK(F14)=TRUE,ISBLANK(G14)=TRUE,ISBLANK(H14)=TRUE,ISBLANK(I14)=TRUE,ISBLANK(J14)=TRUE,ISBLANK(K14)=TRUE,ISBLANK(L14)=TRUE,ISBLANK(M14)=TRUE,ISBLANK(N14)=TRUE,ISBLANK(O14)=TRUE,ISBLANK(P14)=TRUE,ISBLANK(Q14)=TRUE,ISBLANK(R14)=TRUE,ISBLANK(S14)=TRUE,ISBLANK(T14)=TRUE,ISBLANK(U14)=TRUE,ISBLANK(V14)=TRUE,ISBLANK(W14)=TRUE),"",SUM(D14:W14))
A15: 11 | X15: =IF(AND(ISBLANK(D15)=TRUE,ISBLANK(E15)=TRUE,ISBLANK(F15)=TRUE,ISBLANK(G15)=TRUE,ISBLANK(H15)=TRUE,ISBLANK(I15)=TRUE,ISBLANK(J15)=TRUE,ISBLANK(K15)=TRUE,ISBLANK(L15)=TRUE,ISBLANK(M15)=TRUE,ISBLANK(N15)=TRUE,ISBLANK(O15)=TRUE,ISBLANK(P15)=TRUE,ISBLANK(Q15)=TRUE,ISBLANK(R15)=TRUE,ISBLANK(S15)=TRUE,ISBLANK(T15)=TRUE,ISBLANK(U15)=TRUE,ISBLANK(V15)=TRUE,ISBLANK(W15)=TRUE),"",SUM(D15:W15))
A16: 12 | X16: =IF(AND(ISBLANK(D16)=TRUE,ISBLANK(E16)=TRUE,ISBLANK(F16)=TRUE,ISBLANK(G16)=TRUE,ISBLANK(H16)=TRUE,ISBLANK(I16)=TRUE,ISBLANK(J16)=TRUE,ISBLANK(K16)=TRUE,ISBLANK(L16)=TRUE,ISBLANK(M16)=TRUE,ISBLANK(N16)=TRUE,ISBLANK(O16)=TRUE,ISBLANK(P16)=TRUE,ISBLANK(Q16)=TRUE,ISBLANK(R16)=TRUE,ISBLANK(S16)=TRUE,ISBLANK(T16)=TRUE,ISBLANK(U16)=TRUE,ISBLANK(V16)=TRUE,ISBLANK(W16)=TRUE),"",SUM(D16:W16))
A17: 13 | X17: =IF(AND(ISBLANK(D17)=TRUE,ISBLANK(E17)=TRUE,ISBLANK(F17)=TRUE,ISBLANK(G17)=TRUE,ISBLANK(H17)=TRUE,ISBLANK(I17)=TRUE,ISBLANK(J17)=TRUE,ISBLANK(K17)=TRUE,ISBLANK(L17)=TRUE,ISBLANK(M17)=TRUE,ISBLANK(N17)=TRUE,ISBLANK(O17)=TRUE,ISBLANK(P17)=TRUE,ISBLANK(Q17)=TRUE,ISBLANK(R17)=TRUE,ISBLANK(S17)=TRUE,ISBLANK(T17)=TRUE,ISBLANK(U17)=TRUE,ISBLANK(V17)=TRUE,ISBLANK(W17)=TRUE),"",SUM(D17:W17))
A18: 14 | X18: =IF(AND(ISBLANK(D18)=TRUE,ISBLANK(E18)=TRUE,ISBLANK(F18)=TRUE,ISBLANK(G18)=TRUE,ISBLANK(H18)=TRUE,ISBLANK(I18)=TRUE,ISBLANK(J18)=TRUE,ISBLANK(K18)=TRUE,ISBLANK(L18)=TRUE,ISBLANK(M18)=TRUE,ISBLANK(N18)=TRUE,ISBLANK(O18)=TRUE,ISBLANK(P18)=TRUE,ISBLANK(Q18)=TRUE,ISBLANK(R18)=TRUE,ISBLANK(S18)=TRUE,ISBLANK(T18)=TRUE,ISBLANK(U18)=TRUE,ISBLANK(V18)=TRUE,ISBLANK(W18)=TRUE),"",SUM(D18:W18))
A19: 15 | X19: =IF(AND(ISBLANK(D19)=TRUE,ISBLANK(E19)=TRUE,ISBLANK(F19)=TRUE,ISBLANK(G19)=TRUE,ISBLANK(H19)=TRUE,ISBLANK(I19)=TRUE,ISBLANK(J19)=TRUE,ISBLANK(K19)=TRUE,ISBLANK(L19)=TRUE,ISBLANK(M19)=TRUE,ISBLANK(N19)=TRUE,ISBLANK(O19)=TRUE,ISBLANK(P19)=TRUE,ISBLANK(Q19)=TRUE,ISBLANK(R19)=TRUE,ISBLANK(S19)=TRUE,ISBLANK(T19)=TRUE,ISBLANK(U19)=TRUE,ISBLANK(V19)=TRUE,ISBLANK(W19)=TRUE),"",SUM(D19:W19))
... A64: 60 | X64: =IF(AND(ISBLANK(D64)=TRUE,ISBLANK(E64)=TRUE,ISBLANK(F64)=TRUE,ISBLANK(G64)=TRUE,ISBLANK(H64)=TRUE,ISBLANK(I64)=TRUE,ISBLANK(J64)=TRUE,ISBLANK(K64)=TRUE,ISBLANK(L64)=TRUE,ISBLANK(M64)=TRUE,ISBLANK(N64)=TRUE,ISBLANK(O64)=TRUE,ISBLANK(P64)=TRUE,ISBLANK(Q64)=TRUE,ISBLANK(R64)=TRUE,ISBLANK(S64)=TRUE,ISBLANK(T64)=TRUE,ISBLANK(U64)=TRUE,ISBLANK(V64)=TRUE,ISBLANK(W64)=TRUE),"",SUM(D64:W64))

Sheet กลางภาค
A1: ชีท --กลางภาค-- ให้ตั้งชื่อหัวข้อตามความต้องการและกรอกคะแนนเต็มของแต่ล่ะหน่วย ---ช่องใดไม่ใช้งานให้เว้นว่างไว้---
A2: เลขที่ | B2: รหัสนักเรียน | C2: ชื่อหัวข้อ | D2: คะแนนสอบกลางภาค | N2: รวม
D3: 1 | E3: 2 | F3: 3 | G3: 4 | H3: 5 | I3: 6 | J3: 7 | K3: 8 | L3: 9 | M3: 10
C4: คะแนนเต็ม | N4: =IF(AND(ISBLANK(D4)=TRUE,ISBLANK(E4)=TRUE,ISBLANK(F4)=TRUE,ISBLANK(G4)=TRUE,ISBLANK(H4)=TRUE,ISBLANK(I4)=TRUE,ISBLANK(J4)=TRUE,ISBLANK(K4)=TRUE,ISBLANK(L4)=TRUE,ISBLANK(M4)=TRUE),"",SUM(D4:M4))
A5: =คะแนนเก็บ!A5 -> 1 | B5: =คะแนนเก็บ!B5 -> 123 | C5: =คะแนนเก็บ!C5 -> เด็กชายจับจ่าย รักโรงเรียน | N5: =IF(AND(ISBLANK(D5)=TRUE,ISBLANK(E5)=TRUE,ISBLANK(F5)=TRUE,ISBLANK(G5)=TRUE,ISBLANK(H5)=TRUE,ISBLANK(I5)=TRUE,ISBLANK(J5)=TRUE,ISBLANK(K5)=TRUE,ISBLANK(L5)=TRUE,ISBLANK(M5)=TRUE),"",SUM(D5:M5))
A6: =คะแนนเก็บ!A6 -> 2 | B6: =คะแนนเก็บ!B6 -> 456 | C6: =คะแนนเก็บ!C6 -> เด็กชายสคูล ไบร์ท | N6: =IF(AND(ISBLANK(D6)=TRUE,ISBLANK(E6)=TRUE,ISBLANK(F6)=TRUE,ISBLANK(G6)=TRUE,ISBLANK(H6)=TRUE,ISBLANK(I6)=TRUE,ISBLANK(J6)=TRUE,ISBLANK(K6)=TRUE,ISBLANK(L6)=TRUE,ISBLANK(M6)=TRUE),"",SUM(D6:M6))
A7: =คะแนนเก็บ!A7 -> 3 | B7: =คะแนนเก็บ!B7 -> A123 | C7: =คะแนนเก็บ!C7 -> เด็กหญิงน้ำเพชร ใจดี | N7: =IF(AND(ISBLANK(D7)=TRUE,ISBLANK(E7)=TRUE,ISBLANK(F7)=TRUE,ISBLANK(G7)=TRUE,ISBLANK(H7)=TRUE,ISBLANK(I7)=TRUE,ISBLANK(J7)=TRUE,ISBLANK(K7)=TRUE,ISBLANK(L7)=TRUE,ISBLANK(M7)=TRUE),"",SUM(D7:M7))
A8: =คะแนนเก็บ!A8 -> 4 | B8: =คะแนนเก็บ!B8 -> 0 | C8: =คะแนนเก็บ!C8 -> 0 | N8: =IF(AND(ISBLANK(D8)=TRUE,ISBLANK(E8)=TRUE,ISBLANK(F8)=TRUE,ISBLANK(G8)=TRUE,ISBLANK(H8)=TRUE,ISBLANK(I8)=TRUE,ISBLANK(J8)=TRUE,ISBLANK(K8)=TRUE,ISBLANK(L8)=TRUE,ISBLANK(M8)=TRUE),"",SUM(D8:M8))
A9: =คะแนนเก็บ!A9 -> 5 | B9: =คะแนนเก็บ!B9 -> 0 | C9: =คะแนนเก็บ!C9 -> 0 | N9: =IF(AND(ISBLANK(D9)=TRUE,ISBLANK(E9)=TRUE,ISBLANK(F9)=TRUE,ISBLANK(G9)=TRUE,ISBLANK(H9)=TRUE,ISBLANK(I9)=TRUE,ISBLANK(J9)=TRUE,ISBLANK(K9)=TRUE,ISBLANK(L9)=TRUE,ISBLANK(M9)=TRUE),"",SUM(D9:M9))
A10: =คะแนนเก็บ!A10 -> 6 | B10: =คะแนนเก็บ!B10 -> 0 | C10: =คะแนนเก็บ!C10 -> 0 | N10: =IF(AND(ISBLANK(D10)=TRUE,ISBLANK(E10)=TRUE,ISBLANK(F10)=TRUE,ISBLANK(G10)=TRUE,ISBLANK(H10)=TRUE,ISBLANK(I10)=TRUE,ISBLANK(J10)=TRUE,ISBLANK(K10)=TRUE,ISBLANK(L10)=TRUE,ISBLANK(M10)=TRUE),"",SUM(D10:M10))
A11: =คะแนนเก็บ!A11 -> 7 | B11: =คะแนนเก็บ!B11 -> 0 | C11: =คะแนนเก็บ!C11 -> 0 | N11: =IF(AND(ISBLANK(D11)=TRUE,ISBLANK(E11)=TRUE,ISBLANK(F11)=TRUE,ISBLANK(G11)=TRUE,ISBLANK(H11)=TRUE,ISBLANK(I11)=TRUE,ISBLANK(J11)=TRUE,ISBLANK(K11)=TRUE,ISBLANK(L11)=TRUE,ISBLANK(M11)=TRUE),"",SUM(D11:M11))
A12: =คะแนนเก็บ!A12 -> 8 | B12: =คะแนนเก็บ!B12 -> 0 | C12: =คะแนนเก็บ!C12 -> 0 | N12: =IF(AND(ISBLANK(D12)=TRUE,ISBLANK(E12)=TRUE,ISBLANK(F12)=TRUE,ISBLANK(G12)=TRUE,ISBLANK(H12)=TRUE,ISBLANK(I12)=TRUE,ISBLANK(J12)=TRUE,ISBLANK(K12)=TRUE,ISBLANK(L12)=TRUE,ISBLANK(M12)=TRUE),"",SUM(D12:M12))
A13: =คะแนนเก็บ!A13 -> 9 | B13: =คะแนนเก็บ!B13 -> 0 | C13: =คะแนนเก็บ!C13 -> 0 | N13: =IF(AND(ISBLANK(D13)=TRUE,ISBLANK(E13)=TRUE,ISBLANK(F13)=TRUE,ISBLANK(G13)=TRUE,ISBLANK(H13)=TRUE,ISBLANK(I13)=TRUE,ISBLANK(J13)=TRUE,ISBLANK(K13)=TRUE,ISBLANK(L13)=TRUE,ISBLANK(M13)=TRUE),"",SUM(D13:M13))
A14: =คะแนนเก็บ!A14 -> 10 | B14: =คะแนนเก็บ!B14 -> 0 | C14: =คะแนนเก็บ!C14 -> 0 | N14: =IF(AND(ISBLANK(D14)=TRUE,ISBLANK(E14)=TRUE,ISBLANK(F14)=TRUE,ISBLANK(G14)=TRUE,ISBLANK(H14)=TRUE,ISBLANK(I14)=TRUE,ISBLANK(J14)=TRUE,ISBLANK(K14)=TRUE,ISBLANK(L14)=TRUE,ISBLANK(M14)=TRUE),"",SUM(D14:M14))
A15: =คะแนนเก็บ!A15 -> 11 | B15: =คะแนนเก็บ!B15 -> 0 | C15: =คะแนนเก็บ!C15 -> 0 | N15: =IF(AND(ISBLANK(D15)=TRUE,ISBLANK(E15)=TRUE,ISBLANK(F15)=TRUE,ISBLANK(G15)=TRUE,ISBLANK(H15)=TRUE,ISBLANK(I15)=TRUE,ISBLANK(J15)=TRUE,ISBLANK(K15)=TRUE,ISBLANK(L15)=TRUE,ISBLANK(M15)=TRUE),"",SUM(D15:M15))
A16: =คะแนนเก็บ!A16 -> 12 | B16: =คะแนนเก็บ!B16 -> 0 | C16: =คะแนนเก็บ!C16 -> 0 | N16: =IF(AND(ISBLANK(D16)=TRUE,ISBLANK(E16)=TRUE,ISBLANK(F16)=TRUE,ISBLANK(G16)=TRUE,ISBLANK(H16)=TRUE,ISBLANK(I16)=TRUE,ISBLANK(J16)=TRUE,ISBLANK(K16)=TRUE,ISBLANK(L16)=TRUE,ISBLANK(M16)=TRUE),"",SUM(D16:M16))
... A64: =คะแนนเก็บ!A64 -> 60 | B64: =คะแนนเก็บ!B64 -> 0 | C64: =คะแนนเก็บ!C64 -> 0 | N64: =IF(AND(ISBLANK(D64)=TRUE,ISBLANK(E64)=TRUE,ISBLANK(F64)=TRUE,ISBLANK(G64)=TRUE,ISBLANK(H64)=TRUE,ISBLANK(I64)=TRUE,ISBLANK(J64)=TRUE,ISBLANK(K64)=TRUE,ISBLANK(L64)=TRUE,ISBLANK(M64)=TRUE),"",SUM(D64:M64))

Sheet คะแนนเก็บหลังกลางภาค
A1: ชีท --คะแนนเก็บหลังกลางภาค-- ให้ตั้งชื่อหัวข้อตามความต้องการและกรอกคะแนนเต็มของแต่ล่ะหน่วย ---ช่องใดไม่ใช้งานให้เว้นว่างไว้---
A2: เลขที่ | B2: รหัสนักเรียน | C2: ชื่อหัวข้อ | D2: คะแนนเก็บ/ตัวชี้วัด | X2: รวม
D3: 1 | E3: 2 | F3: 3 | G3: 4 | H3: 5 | I3: 6 | J3: 7 | K3: 8 | L3: 9 | M3: 10 | N3: 11 | O3: 12 | P3: 13 | Q3: 14 | R3: 15 | S3: 16 | T3: 17 | U3: 18 | V3: 19 | W3: 20
C4: คะแนนเต็ม | X4: =IF(AND(ISBLANK(D4)=TRUE,ISBLANK(E4)=TRUE,ISBLANK(F4)=TRUE,ISBLANK(G4)=TRUE,ISBLANK(H4)=TRUE,ISBLANK(I4)=TRUE,ISBLANK(J4)=TRUE,ISBLANK(K4)=TRUE,ISBLANK(L4)=TRUE,ISBLANK(M4)=TRUE,ISBLANK(N4)=TRUE,ISBLANK(O4)=TRUE,ISBLANK(P4)=TRUE,ISBLANK(Q4)=TRUE,ISBLANK(R4)=TRUE,ISBLANK(S4)=TRUE,ISBLANK(T4)=TRUE,ISBLANK(U4)=TRUE,ISBLANK(V4)=TRUE,ISBLANK(W4)=TRUE),"",SUM(D4:W4))
A5: 1 | B5: =คะแนนเก็บ!B5 -> 123 | C5: =คะแนนเก็บ!C5 -> เด็กชายจับจ่าย รักโรงเรียน | X5: =IF(AND(ISBLANK(D5)=TRUE,ISBLANK(E5)=TRUE,ISBLANK(F5)=TRUE,ISBLANK(G5)=TRUE,ISBLANK(H5)=TRUE,ISBLANK(I5)=TRUE,ISBLANK(J5)=TRUE,ISBLANK(K5)=TRUE,ISBLANK(L5)=TRUE,ISBLANK(M5)=TRUE,ISBLANK(N5)=TRUE,ISBLANK(O5)=TRUE,ISBLANK(P5)=TRUE,ISBLANK(Q5)=TRUE,ISBLANK(R5)=TRUE,ISBLANK(S5)=TRUE,ISBLANK(T5)=TRUE,ISBLANK(U5)=TRUE,ISBLANK(V5)=TRUE,ISBLANK(W5)=TRUE),"",SUM(D5:W5))
A6: 2 | B6: =คะแนนเก็บ!B6 -> 456 | C6: =คะแนนเก็บ!C6 -> เด็กชายสคูล ไบร์ท | X6: =IF(AND(ISBLANK(D6)=TRUE,ISBLANK(E6)=TRUE,ISBLANK(F6)=TRUE,ISBLANK(G6)=TRUE,ISBLANK(H6)=TRUE,ISBLANK(I6)=TRUE,ISBLANK(J6)=TRUE,ISBLANK(K6)=TRUE,ISBLANK(L6)=TRUE,ISBLANK(M6)=TRUE,ISBLANK(N6)=TRUE,ISBLANK(O6)=TRUE,ISBLANK(P6)=TRUE,ISBLANK(Q6)=TRUE,ISBLANK(R6)=TRUE,ISBLANK(S6)=TRUE,ISBLANK(T6)=TRUE,ISBLANK(U6)=TRUE,ISBLANK(V6)=TRUE,ISBLANK(W6)=TRUE),"",SUM(D6:W6))
A7: 3 | B7: =คะแนนเก็บ!B7 -> A123 | C7: =คะแนนเก็บ!C7 -> เด็กหญิงน้ำเพชร ใจดี | X7: =IF(AND(ISBLANK(D7)=TRUE,ISBLANK(E7)=TRUE,ISBLANK(F7)=TRUE,ISBLANK(G7)=TRUE,ISBLANK(H7)=TRUE,ISBLANK(I7)=TRUE,ISBLANK(J7)=TRUE,ISBLANK(K7)=TRUE,ISBLANK(L7)=TRUE,ISBLANK(M7)=TRUE,ISBLANK(N7)=TRUE,ISBLANK(O7)=TRUE,ISBLANK(P7)=TRUE,ISBLANK(Q7)=TRUE,ISBLANK(R7)=TRUE,ISBLANK(S7)=TRUE,ISBLANK(T7)=TRUE,ISBLANK(U7)=TRUE,ISBLANK(V7)=TRUE,ISBLANK(W7)=TRUE),"",SUM(D7:W7))
A8: 4 | B8: =คะแนนเก็บ!B8 -> 0 | C8: =คะแนนเก็บ!C8 -> 0 | X8: =IF(AND(ISBLANK(D8)=TRUE,ISBLANK(E8)=TRUE,ISBLANK(F8)=TRUE,ISBLANK(G8)=TRUE,ISBLANK(H8)=TRUE,ISBLANK(I8)=TRUE,ISBLANK(J8)=TRUE,ISBLANK(K8)=TRUE,ISBLANK(L8)=TRUE,ISBLANK(M8)=TRUE,ISBLANK(N8)=TRUE,ISBLANK(O8)=TRUE,ISBLANK(P8)=TRUE,ISBLANK(Q8)=TRUE,ISBLANK(R8)=TRUE,ISBLANK(S8)=TRUE,ISBLANK(T8)=TRUE,ISBLANK(U8)=TRUE,ISBLANK(V8)=TRUE,ISBLANK(W8)=TRUE),"",SUM(D8:W8))
A9: 5 | B9: =คะแนนเก็บ!B9 -> 0 | C9: =คะแนนเก็บ!C9 -> 0 | X9: =IF(AND(ISBLANK(D9)=TRUE,ISBLANK(E9)=TRUE,ISBLANK(F9)=TRUE,ISBLANK(G9)=TRUE,ISBLANK(H9)=TRUE,ISBLANK(I9)=TRUE,ISBLANK(J9)=TRUE,ISBLANK(K9)=TRUE,ISBLANK(L9)=TRUE,ISBLANK(M9)=TRUE,ISBLANK(N9)=TRUE,ISBLANK(O9)=TRUE,ISBLANK(P9)=TRUE,ISBLANK(Q9)=TRUE,ISBLANK(R9)=TRUE,ISBLANK(S9)=TRUE,ISBLANK(T9)=TRUE,ISBLANK(U9)=TRUE,ISBLANK(V9)=TRUE,ISBLANK(W9)=TRUE),"",SUM(D9:W9))
A10: 6 | B10: =คะแนนเก็บ!B10 -> 0 | C10: =คะแนนเก็บ!C10 -> 0 | X10: =IF(AND(ISBLANK(D10)=TRUE,ISBLANK(E10)=TRUE,ISBLANK(F10)=TRUE,ISBLANK(G10)=TRUE,ISBLANK(H10)=TRUE,ISBLANK(I10)=TRUE,ISBLANK(J10)=TRUE,ISBLANK(K10)=TRUE,ISBLANK(L10)=TRUE,ISBLANK(M10)=TRUE,ISBLANK(N10)=TRUE,ISBLANK(O10)=TRUE,ISBLANK(P10)=TRUE,ISBLANK(Q10)=TRUE,ISBLANK(R10)=TRUE,ISBLANK(S10)=TRUE,ISBLANK(T10)=TRUE,ISBLANK(U10)=TRUE,ISBLANK(V10)=TRUE,ISBLANK(W10)=TRUE),"",SUM(D10:W10))
A11: 7 | B11: =คะแนนเก็บ!B11 -> 0 | C11: =คะแนนเก็บ!C11 -> 0 | X11: =IF(AND(ISBLANK(D11)=TRUE,ISBLANK(E11)=TRUE,ISBLANK(F11)=TRUE,ISBLANK(G11)=TRUE,ISBLANK(H11)=TRUE,ISBLANK(I11)=TRUE,ISBLANK(J11)=TRUE,ISBLANK(K11)=TRUE,ISBLANK(L11)=TRUE,ISBLANK(M11)=TRUE,ISBLANK(N11)=TRUE,ISBLANK(O11)=TRUE,ISBLANK(P11)=TRUE,ISBLANK(Q11)=TRUE,ISBLANK(R11)=TRUE,ISBLANK(S11)=TRUE,ISBLANK(T11)=TRUE,ISBLANK(U11)=TRUE,ISBLANK(V11)=TRUE,ISBLANK(W11)=TRUE),"",SUM(D11:W11))
A12: 8 | B12: =คะแนนเก็บ!B12 -> 0 | C12: =คะแนนเก็บ!C12 -> 0 | X12: =IF(AND(ISBLANK(D12)=TRUE,ISBLANK(E12)=TRUE,ISBLANK(F12)=TRUE,ISBLANK(G12)=TRUE,ISBLANK(H12)=TRUE,ISBLANK(I12)=TRUE,ISBLANK(J12)=TRUE,ISBLANK(K12)=TRUE,ISBLANK(L12)=TRUE,ISBLANK(M12)=TRUE,ISBLANK(N12)=TRUE,ISBLANK(O12)=TRUE,ISBLANK(P12)=TRUE,ISBLANK(Q12)=TRUE,ISBLANK(R12)=TRUE,ISBLANK(S12)=TRUE,ISBLANK(T12)=TRUE,ISBLANK(U12)=TRUE,ISBLANK(V12)=TRUE,ISBLANK(W12)=TRUE),"",SUM(D12:W12))
A13: 9 | B13: =คะแนนเก็บ!B13 -> 0 | C13: =คะแนนเก็บ!C13 -> 0 | X13: =IF(AND(ISBLANK(D13)=TRUE,ISBLANK(E13)=TRUE,ISBLANK(F13)=TRUE,ISBLANK(G13)=TRUE,ISBLANK(H13)=TRUE,ISBLANK(I13)=TRUE,ISBLANK(J13)=TRUE,ISBLANK(K13)=TRUE,ISBLANK(L13)=TRUE,ISBLANK(M13)=TRUE,ISBLANK(N13)=TRUE,ISBLANK(O13)=TRUE,ISBLANK(P13)=TRUE,ISBLANK(Q13)=TRUE,ISBLANK(R13)=TRUE,ISBLANK(S13)=TRUE,ISBLANK(T13)=TRUE,ISBLANK(U13)=TRUE,ISBLANK(V13)=TRUE,ISBLANK(W13)=TRUE),"",SUM(D13:W13))
A14: 10 | B14: =คะแนนเก็บ!B14 -> 0 | C14: =คะแนนเก็บ!C14 -> 0 | X14: =IF(AND(ISBLANK(D14)=TRUE,ISBLANK(E14)=TRUE,ISBLANK(F14)=TRUE,ISBLANK(G14)=TRUE,ISBLANK(H14)=TRUE,ISBLANK(I14)=TRUE,ISBLANK(J14)=TRUE,ISBLANK(K14)=TRUE,ISBLANK(L14)=TRUE,ISBLANK(M14)=TRUE,ISBLANK(N14)=TRUE,ISBLANK(O14)=TRUE,ISBLANK(P14)=TRUE,ISBLANK(Q14)=TRUE,ISBLANK(R14)=TRUE,ISBLANK(S14)=TRUE,ISBLANK(T14)=TRUE,ISBLANK(U14)=TRUE,ISBLANK(V14)=TRUE,ISBLANK(W14)=TRUE),"",SUM(D14:W14))
A15: 11 | B15: =คะแนนเก็บ!B15 -> 0 | C15: =คะแนนเก็บ!C15 -> 0 | X15: =IF(AND(ISBLANK(D15)=TRUE,ISBLANK(E15)=TRUE,ISBLANK(F15)=TRUE,ISBLANK(G15)=TRUE,ISBLANK(H15)=TRUE,ISBLANK(I15)=TRUE,ISBLANK(J15)=TRUE,ISBLANK(K15)=TRUE,ISBLANK(L15)=TRUE,ISBLANK(M15)=TRUE,ISBLANK(N15)=TRUE,ISBLANK(O15)=TRUE,ISBLANK(P15)=TRUE,ISBLANK(Q15)=TRUE,ISBLANK(R15)=TRUE,ISBLANK(S15)=TRUE,ISBLANK(T15)=TRUE,ISBLANK(U15)=TRUE,ISBLANK(V15)=TRUE,ISBLANK(W15)=TRUE),"",SUM(D15:W15))
A16: 12 | B16: =คะแนนเก็บ!B16 -> 0 | C16: =คะแนนเก็บ!C16 -> 0 | X16: =IF(AND(ISBLANK(D16)=TRUE,ISBLANK(E16)=TRUE,ISBLANK(F16)=TRUE,ISBLANK(G16)=TRUE,ISBLANK(H16)=TRUE,ISBLANK(I16)=TRUE,ISBLANK(J16)=TRUE,ISBLANK(K16)=TRUE,ISBLANK(L16)=TRUE,ISBLANK(M16)=TRUE,ISBLANK(N16)=TRUE,ISBLANK(O16)=TRUE,ISBLANK(P16)=TRUE,ISBLANK(Q16)=TRUE,ISBLANK(R16)=TRUE,ISBLANK(S16)=TRUE,ISBLANK(T16)=TRUE,ISBLANK(U16)=TRUE,ISBLANK(V16)=TRUE,ISBLANK(W16)=TRUE),"",SUM(D16:W16))
... A64: 60 | B64: =คะแนนเก็บ!B64 -> 0 | C64: =คะแนนเก็บ!C64 -> 0 | X64: =IF(AND(ISBLANK(D64)=TRUE,ISBLANK(E64)=TRUE,ISBLANK(F64)=TRUE,ISBLANK(G64)=TRUE,ISBLANK(H64)=TRUE,ISBLANK(I64)=TRUE,ISBLANK(J64)=TRUE,ISBLANK(K64)=TRUE,ISBLANK(L64)=TRUE,ISBLANK(M64)=TRUE,ISBLANK(N64)=TRUE,ISBLANK(O64)=TRUE,ISBLANK(P64)=TRUE,ISBLANK(Q64)=TRUE,ISBLANK(R64)=TRUE,ISBLANK(S64)=TRUE,ISBLANK(T64)=TRUE,ISBLANK(U64)=TRUE,ISBLANK(V64)=TRUE,ISBLANK(W64)=TRUE),"",SUM(D64:W64))

Sheet ปลายภาค
A1: ชีท --ปลายภาค-- ให้ตั้งชื่อหัวข้อตามความต้องการและกรอกคะแนนเต็มของแต่ล่ะหน่วย ---ช่องใดไม่ใช้งานให้เว้นว่างไว้---
A2: เลขที่ | B2: รหัสนักเรียน | C2: ชื่อหัวข้อ | D2: คะแนนสอบปลายภาค | N2: รวม
D3: 1 | E3: 2 | F3: 3 | G3: 4 | H3: 5 | I3: 6 | J3: 7 | K3: 8 | L3: 9 | M3: 10
C4: คะแนนเต็ม | N4: =IF(AND(ISBLANK(D4)=TRUE,ISBLANK(E4)=TRUE,ISBLANK(F4)=TRUE,ISBLANK(G4)=TRUE,ISBLANK(H4)=TRUE,ISBLANK(I4)=TRUE,ISBLANK(J4)=TRUE,ISBLANK(K4)=TRUE,ISBLANK(L4)=TRUE,ISBLANK(M4)=TRUE),"",SUM(D4:M4))
A5: =คะแนนเก็บ!A5 -> 1 | B5: =คะแนนเก็บ!B5 -> 123 | C5: =คะแนนเก็บ!C5 -> เด็กชายจับจ่าย รักโรงเรียน | N5: =IF(AND(ISBLANK(D5)=TRUE,ISBLANK(E5)=TRUE,ISBLANK(F5)=TRUE,ISBLANK(G5)=TRUE,ISBLANK(H5)=TRUE,ISBLANK(I5)=TRUE,ISBLANK(J5)=TRUE,ISBLANK(K5)=TRUE,ISBLANK(L5)=TRUE,ISBLANK(M5)=TRUE),"",SUM(D5:M5))
A6: =คะแนนเก็บ!A6 -> 2 | B6: =คะแนนเก็บ!B6 -> 456 | C6: =คะแนนเก็บ!C6 -> เด็กชายสคูล ไบร์ท | N6: =IF(AND(ISBLANK(D6)=TRUE,ISBLANK(E6)=TRUE,ISBLANK(F6)=TRUE,ISBLANK(G6)=TRUE,ISBLANK(H6)=TRUE,ISBLANK(I6)=TRUE,ISBLANK(J6)=TRUE,ISBLANK(K6)=TRUE,ISBLANK(L6)=TRUE,ISBLANK(M6)=TRUE),"",SUM(D6:M6))
A7: =คะแนนเก็บ!A7 -> 3 | B7: =คะแนนเก็บ!B7 -> A123 | C7: =คะแนนเก็บ!C7 -> เด็กหญิงน้ำเพชร ใจดี | N7: =IF(AND(ISBLANK(D7)=TRUE,ISBLANK(E7)=TRUE,ISBLANK(F7)=TRUE,ISBLANK(G7)=TRUE,ISBLANK(H7)=TRUE,ISBLANK(I7)=TRUE,ISBLANK(J7)=TRUE,ISBLANK(K7)=TRUE,ISBLANK(L7)=TRUE,ISBLANK(M7)=TRUE),"",SUM(D7:M7))
A8: =คะแนนเก็บ!A8 -> 4 | B8: =คะแนนเก็บ!B8 -> 0 | C8: =คะแนนเก็บ!C8 -> 0 | N8: =IF(AND(ISBLANK(D8)=TRUE,ISBLANK(E8)=TRUE,ISBLANK(F8)=TRUE,ISBLANK(G8)=TRUE,ISBLANK(H8)=TRUE,ISBLANK(I8)=TRUE,ISBLANK(J8)=TRUE,ISBLANK(K8)=TRUE,ISBLANK(L8)=TRUE,ISBLANK(M8)=TRUE),"",SUM(D8:M8))
A9: =คะแนนเก็บ!A9 -> 5 | B9: =คะแนนเก็บ!B9 -> 0 | C9: =คะแนนเก็บ!C9 -> 0 | N9: =IF(AND(ISBLANK(D9)=TRUE,ISBLANK(E9)=TRUE,ISBLANK(F9)=TRUE,ISBLANK(G9)=TRUE,ISBLANK(H9)=TRUE,ISBLANK(I9)=TRUE,ISBLANK(J9)=TRUE,ISBLANK(K9)=TRUE,ISBLANK(L9)=TRUE,ISBLANK(M9)=TRUE),"",SUM(D9:M9))
A10: =คะแนนเก็บ!A10 -> 6 | B10: =คะแนนเก็บ!B10 -> 0 | C10: =คะแนนเก็บ!C10 -> 0 | N10: =IF(AND(ISBLANK(D10)=TRUE,ISBLANK(E10)=TRUE,ISBLANK(F10)=TRUE,ISBLANK(G10)=TRUE,ISBLANK(H10)=TRUE,ISBLANK(I10)=TRUE,ISBLANK(J10)=TRUE,ISBLANK(K10)=TRUE,ISBLANK(L10)=TRUE,ISBLANK(M10)=TRUE),"",SUM(D10:M10))
A11: =คะแนนเก็บ!A11 -> 7 | B11: =คะแนนเก็บ!B11 -> 0 | C11: =คะแนนเก็บ!C11 -> 0 | N11: =IF(AND(ISBLANK(D11)=TRUE,ISBLANK(E11)=TRUE,ISBLANK(F11)=TRUE,ISBLANK(G11)=TRUE,ISBLANK(H11)=TRUE,ISBLANK(I11)=TRUE,ISBLANK(J11)=TRUE,ISBLANK(K11)=TRUE,ISBLANK(L11)=TRUE,ISBLANK(M11)=TRUE),"",SUM(D11:M11))
A12: =คะแนนเก็บ!A12 -> 8 | B12: =คะแนนเก็บ!B12 -> 0 | C12: =คะแนนเก็บ!C12 -> 0 | N12: =IF(AND(ISBLANK(D12)=TRUE,ISBLANK(E12)=TRUE,ISBLANK(F12)=TRUE,ISBLANK(G12)=TRUE,ISBLANK(H12)=TRUE,ISBLANK(I12)=TRUE,ISBLANK(J12)=TRUE,ISBLANK(K12)=TRUE,ISBLANK(L12)=TRUE,ISBLANK(M12)=TRUE),"",SUM(D12:M12))
A13: =คะแนนเก็บ!A13 -> 9 | B13: =คะแนนเก็บ!B13 -> 0 | C13: =คะแนนเก็บ!C13 -> 0 | N13: =IF(AND(ISBLANK(D13)=TRUE,ISBLANK(E13)=TRUE,ISBLANK(F13)=TRUE,ISBLANK(G13)=TRUE,ISBLANK(H13)=TRUE,ISBLANK(I13)=TRUE,ISBLANK(J13)=TRUE,ISBLANK(K13)=TRUE,ISBLANK(L13)=TRUE,ISBLANK(M13)=TRUE),"",SUM(D13:M13))
A14: =คะแนนเก็บ!A14 -> 10 | B14: =คะแนนเก็บ!B14 -> 0 | C14: =คะแนนเก็บ!C14 -> 0 | N14: =IF(AND(ISBLANK(D14)=TRUE,ISBLANK(E14)=TRUE,ISBLANK(F14)=TRUE,ISBLANK(G14)=TRUE,ISBLANK(H14)=TRUE,ISBLANK(I14)=TRUE,ISBLANK(J14)=TRUE,ISBLANK(K14)=TRUE,ISBLANK(L14)=TRUE,ISBLANK(M14)=TRUE),"",SUM(D14:M14))
A15: =คะแนนเก็บ!A15 -> 11 | B15: =คะแนนเก็บ!B15 -> 0 | C15: =คะแนนเก็บ!C15 -> 0 | N15: =IF(AND(ISBLANK(D15)=TRUE,ISBLANK(E15)=TRUE,ISBLANK(F15)=TRUE,ISBLANK(G15)=TRUE,ISBLANK(H15)=TRUE,ISBLANK(I15)=TRUE,ISBLANK(J15)=TRUE,ISBLANK(K15)=TRUE,ISBLANK(L15)=TRUE,ISBLANK(M15)=TRUE),"",SUM(D15:M15))
A16: =คะแนนเก็บ!A16 -> 12 | B16: =คะแนนเก็บ!B16 -> 0 | C16: =คะแนนเก็บ!C16 -> 0 | N16: =IF(AND(ISBLANK(D16)=TRUE,ISBLANK(E16)=TRUE,ISBLANK(F16)=TRUE,ISBLANK(G16)=TRUE,ISBLANK(H16)=TRUE,ISBLANK(I16)=TRUE,ISBLANK(J16)=TRUE,ISBLANK(K16)=TRUE,ISBLANK(L16)=TRUE,ISBLANK(M16)=TRUE),"",SUM(D16:M16))
... A64: =คะแนนเก็บ!A64 -> 60 | B64: =คะแนนเก็บ!B64 -> 0 | C64: =คะแนนเก็บ!C64 -> 0 | N64: =IF(AND(ISBLANK(D64)=TRUE,ISBLANK(E64)=TRUE,ISBLANK(F64)=TRUE,ISBLANK(G64)=TRUE,ISBLANK(H64)=TRUE,ISBLANK(I64)=TRUE,ISBLANK(J64)=TRUE,ISBLANK(K64)=TRUE,ISBLANK(L64)=TRUE,ISBLANK(M64)=TRUE),"",SUM(D64:M64))

Sheet คุณลักษณะอันพึงประสงค์
A1: ชีท --คุณลักษณะอันพึงประสงค์-- ---ช่องใดไม่ใช้งานให้เว้นว่างไว้---
A2: เลขที่ | B2: รหัสนักเรียน | C2: ชื่อหัวข้อ | D2: คะแนนสอบปลายภาค | X2: รวม
D3: 1 รักชาติ ศาสน์ กษัตริย์ | E3: 2 ซื่อสัตย์สุจริต | F3: 3 มีวินัย | G3: 4 ใฝ่เรียนรู้ | H3: 5 อยู่อย่างพอเพียง | I3: 6 มุ่งมั่นในการทำงาน | J3: 7 รักความเป็นไทย | K3: 8 มีจิตสาธารณะ | L3: 9 | M3: 10 | N3: 11 | O3: 12 | P3: 13 | Q3: 14 | R3: 15 | S3: 16 | T3: 17 | U3: 18 | V3: 19 | W3: 20
C4: คะแนนเต็ม | D4: 3 | E4: 3 | F4: 3 | G4: 3 | H4: 3 | I4: 3 | J4: 3 | K4: 3 | X4: =IFERROR(MAX(_xlfn.MODE.MULT(D4:W4)), "") -> 3 | Y4: ข้อควรระวัง : คะแนนเต็มต้องตรงกับหน้าบันทึกคะแนน
A5: =คะแนนเก็บ!A5 -> 1 | B5: =คะแนนเก็บ!B5 -> 123 | C5: =คะแนนเก็บ!C5 -> เด็กชายจับจ่าย รักโรงเรียน | X5: =IFERROR(MAX(_xlfn.MODE.MULT(D5:W5)), "")
A6: =คะแนนเก็บ!A6 -> 2 | B6: =คะแนนเก็บ!B6 -> 456 | C6: =คะแนนเก็บ!C6 -> เด็กชายสคูล ไบร์ท | X6: =IFERROR(MAX(_xlfn.MODE.MULT(D6:W6)), "")
A7: =คะแนนเก็บ!A7 -> 3 | B7: =คะแนนเก็บ!B7 -> A123 | C7: =คะแนนเก็บ!C7 -> เด็กหญิงน้ำเพชร ใจดี | X7: =IFERROR(MAX(_xlfn.MODE.MULT(D7:W7)), "")
A8: =คะแนนเก็บ!A8 -> 4 | B8: =คะแนนเก็บ!B8 -> 0 | C8: =คะแนนเก็บ!C8 -> 0 | X8: =IFERROR(MAX(_xlfn.MODE.MULT(D8:W8)), "")
A9: =คะแนนเก็บ!A9 -> 5 | B9: =คะแนนเก็บ!B9 -> 0 | C9: =คะแนนเก็บ!C9 -> 0 | X9: =IFERROR(MAX(_xlfn.MODE.MULT(D9:W9)), "")
A10: =คะแนนเก็บ!A10 -> 6 | B10: =คะแนนเก็บ!B10 -> 0 | C10: =คะแนนเก็บ!C10 -> 0 | X10: =IFERROR(MAX(_xlfn.MODE.MULT(D10:W10)), "")
A11: =คะแนนเก็บ!A11 -> 7 | B11: =คะแนนเก็บ!B11 -> 0 | C11: =คะแนนเก็บ!C11 -> 0 | X11: =IFERROR(MAX(_xlfn.MODE.MULT(D11:W11)), "")
A12: =คะแนนเก็บ!A12 -> 8 | B12: =คะแนนเก็บ!B12 -> 0 | C12: =คะแนนเก็บ!C12 -> 0 | X12: =IFERROR(MAX(_xlfn.MODE.MULT(D12:W12)), "")
A13: =คะแนนเก็บ!A13 -> 9 | B13: =คะแนนเก็บ!B13 -> 0 | C13: =คะแนนเก็บ!C13 -> 0 | X13: =IFERROR(MAX(_xlfn.MODE.MULT(D13:W13)), "")
A14: =คะแนนเก็บ!A14 -> 10 | B14: =คะแนนเก็บ!B14 -> 0 | C14: =คะแนนเก็บ!C14 -> 0 | X14: =IFERROR(MAX(_xlfn.MODE.MULT(D14:W14)), "")
A15: =คะแนนเก็บ!A15 -> 11 | B15: =คะแนนเก็บ!B15 -> 0 | C15: =คะแนนเก็บ!C15 -> 0 | X15: =IFERROR(MAX(_xlfn.MODE.MULT(D15:W15)), "")
A16: =คะแนนเก็บ!A16 -> 12 | B16: =คะแนนเก็บ!B16 -> 0 | C16: =คะแนนเก็บ!C16 -> 0 | X16: =IFERROR(MAX(_xlfn.MODE.MULT(D16:W16)), "")
... A63: =คะแนนเก็บ!A63 -> 59 | B63: =คะแนนเก็บ!B63 -> 0 | C63: =คะแนนเก็บ!C63 -> 0 | X63: =IFERROR(MAX(_xlfn.MODE.MULT(D63:W63)), "")
A64: =คะแนนเก็บ!A64 -> 60 | B64: =คะแนนเก็บ!B64 -> 0 | C64: =คะแนนเก็บ!C64 -> 0 | N64: 2 | W64: 1 | X64: =IFERROR(MAX(_xlfn.MODE.MULT(D64:W64)), "")

Sheet อ่านคิดวิเคราะห์
A1: ชีท --อ่าน คิด วิเคราะห์-- หากให้ระบบคำนวณอัติโนมัติไม่ต้องทำอะไรในหน้านี้ให้ปล่อยว่างไว้
A2: เลขที่ | B2: รหัสนักเรียน | C2: ชื่อหัวข้อ | D2: อ่านคิดวิเคราะห์และเขียน | I2: รวม
D3: 1 การอ่าน | E3: 2 การคิดวิเคราะห์ | F3: 3 การเขียน
C4: คะแนนเต็ม | D4: 3 | E4: 3 | F4: 3 | I4: =IFERROR(MAX(_xlfn.MODE.MULT(D4:H4)), "") -> 3 | J4: ข้อควรระวัง : คะแนนเต็มต้องตรงกับหน้าบันทึกคะแนน
A5: =คะแนนเก็บ!A5 -> 1 | B5: =คะแนนเก็บ!B5 -> 123 | C5: =คะแนนเก็บ!C5 -> เด็กชายจับจ่าย รักโรงเรียน | I5: =IFERROR(MAX(_xlfn.MODE.MULT(D5:H5)), "")
A6: =คะแนนเก็บ!A6 -> 2 | B6: =คะแนนเก็บ!B6 -> 456 | C6: =คะแนนเก็บ!C6 -> เด็กชายสคูล ไบร์ท | I6: =IFERROR(MAX(_xlfn.MODE.MULT(D6:H6)), "")
A7: =คะแนนเก็บ!A7 -> 3 | B7: =คะแนนเก็บ!B7 -> A123 | C7: =คะแนนเก็บ!C7 -> เด็กหญิงน้ำเพชร ใจดี | I7: =IFERROR(MAX(_xlfn.MODE.MULT(D7:H7)), "")
A8: =คะแนนเก็บ!A8 -> 4 | B8: =คะแนนเก็บ!B8 -> 0 | C8: =คะแนนเก็บ!C8 -> 0 | I8: =IFERROR(MAX(_xlfn.MODE.MULT(D8:H8)), "")
A9: =คะแนนเก็บ!A9 -> 5 | B9: =คะแนนเก็บ!B9 -> 0 | C9: =คะแนนเก็บ!C9 -> 0 | I9: =IFERROR(MAX(_xlfn.MODE.MULT(D9:H9)), "")
A10: =คะแนนเก็บ!A10 -> 6 | B10: =คะแนนเก็บ!B10 -> 0 | C10: =คะแนนเก็บ!C10 -> 0 | I10: =IFERROR(MAX(_xlfn.MODE.MULT(D10:H10)), "")
A11: =คะแนนเก็บ!A11 -> 7 | B11: =คะแนนเก็บ!B11 -> 0 | C11: =คะแนนเก็บ!C11 -> 0 | I11: =IFERROR(MAX(_xlfn.MODE.MULT(D11:H11)), "")
A12: =คะแนนเก็บ!A12 -> 8 | B12: =คะแนนเก็บ!B12 -> 0 | C12: =คะแนนเก็บ!C12 -> 0 | I12: =IFERROR(MAX(_xlfn.MODE.MULT(D12:H12)), "")
A13: =คะแนนเก็บ!A13 -> 9 | B13: =คะแนนเก็บ!B13 -> 0 | C13: =คะแนนเก็บ!C13 -> 0 | I13: =IFERROR(MAX(_xlfn.MODE.MULT(D13:H13)), "")
A14: =คะแนนเก็บ!A14 -> 10 | B14: =คะแนนเก็บ!B14 -> 0 | C14: =คะแนนเก็บ!C14 -> 0 | I14: =IFERROR(MAX(_xlfn.MODE.MULT(D14:H14)), "")
A15: =คะแนนเก็บ!A15 -> 11 | B15: =คะแนนเก็บ!B15 -> 0 | C15: =คะแนนเก็บ!C15 -> 0 | I15: =IFERROR(MAX(_xlfn.MODE.MULT(D15:H15)), "")
A16: =คะแนนเก็บ!A16 -> 12 | B16: =คะแนนเก็บ!B16 -> 0 | C16: =คะแนนเก็บ!C16 -> 0 | I16: =IFERROR(MAX(_xlfn.MODE.MULT(D16:H16)), "")
... A64: =คะแนนเก็บ!A64 -> 60 | B64: =คะแนนเก็บ!B64 -> 0 | C64: =คะแนนเก็บ!C64 -> 0 | I64: =IFERROR(MAX(_xlfn.MODE.MULT(D64:H64)), "")

Sheet สมรรถนะ
A1: ชีท --สมรรถนะ--
A2: เลขที่ | B2: รหัสนักเรียน | C2: ชื่อหัวข้อ | D2: สมรรถนะ | N2: รวม
D3: 1 หัวข้อตามที่ตั้งค่าในระบบ | E3: 2 หัวข้อตามที่ตั้งค่าในระบบ | F3: 3 หัวข้อตามที่ตั้งค่าในระบบ | G3: 4 หัวข้อตามที่ตั้งค่าในระบบ | H3: 5 หัวข้อตามที่ตั้งค่าในระบบ | I3: 6 หัวข้อตามที่ตั้งค่าในระบบ | J3: 7 หัวข้อตามที่ตั้งค่าในระบบ | K3: 8 หัวข้อตามที่ตั้งค่าในระบบ | L3: 9 หัวข้อตามที่ตั้งค่าในระบบ | M3: 10 หัวข้อตามที่ตั้งค่าในระบบ
C4: คะแนนเต็ม | D4: 3 | E4: 3 | F4: 3 | G4: 3 | H4: 3 | N4: =IFERROR(MAX(_xlfn.MODE.MULT(D4:M4)), "") -> 3 | O4: ข้อควรระวัง : คะแนนเต็มต้องตรงกับหน้าบันทึกคะแนน
A5: =คะแนนเก็บ!A5 -> 1 | B5: =คะแนนเก็บ!B5 -> 123 | C5: =คะแนนเก็บ!C5 -> เด็กชายจับจ่าย รักโรงเรียน | N5: =IFERROR(MAX(_xlfn.MODE.MULT(D5:M5)), "")
A6: =คะแนนเก็บ!A6 -> 2 | B6: =คะแนนเก็บ!B6 -> 456 | C6: =คะแนนเก็บ!C6 -> เด็กชายสคูล ไบร์ท | N6: =IFERROR(MAX(_xlfn.MODE.MULT(D6:M6)), "")
A7: =คะแนนเก็บ!A7 -> 3 | B7: =คะแนนเก็บ!B7 -> A123 | C7: =คะแนนเก็บ!C7 -> เด็กหญิงน้ำเพชร ใจดี | N7: =IFERROR(MAX(_xlfn.MODE.MULT(D7:M7)), "")
A8: =คะแนนเก็บ!A8 -> 4 | B8: =คะแนนเก็บ!B8 -> 0 | C8: =คะแนนเก็บ!C8 -> 0 | N8: =IFERROR(MAX(_xlfn.MODE.MULT(D8:M8)), "")
A9: =คะแนนเก็บ!A9 -> 5 | B9: =คะแนนเก็บ!B9 -> 0 | C9: =คะแนนเก็บ!C9 -> 0 | N9: =IFERROR(MAX(_xlfn.MODE.MULT(D9:M9)), "")
A10: =คะแนนเก็บ!A10 -> 6 | B10: =คะแนนเก็บ!B10 -> 0 | C10: =คะแนนเก็บ!C10 -> 0 | N10: =IFERROR(MAX(_xlfn.MODE.MULT(D10:M10)), "")
A11: =คะแนนเก็บ!A11 -> 7 | B11: =คะแนนเก็บ!B11 -> 0 | C11: =คะแนนเก็บ!C11 -> 0 | N11: =IFERROR(MAX(_xlfn.MODE.MULT(D11:M11)), "")
A12: =คะแนนเก็บ!A12 -> 8 | B12: =คะแนนเก็บ!B12 -> 0 | C12: =คะแนนเก็บ!C12 -> 0 | N12: =IFERROR(MAX(_xlfn.MODE.MULT(D12:M12)), "")
A13: =คะแนนเก็บ!A13 -> 9 | B13: =คะแนนเก็บ!B13 -> 0 | C13: =คะแนนเก็บ!C13 -> 0 | N13: =IFERROR(MAX(_xlfn.MODE.MULT(D13:M13)), "")
A14: =คะแนนเก็บ!A14 -> 10 | B14: =คะแนนเก็บ!B14 -> 0 | C14: =คะแนนเก็บ!C14 -> 0 | N14: =IFERROR(MAX(_xlfn.MODE.MULT(D14:M14)), "")
A15: =คะแนนเก็บ!A15 -> 11 | B15: =คะแนนเก็บ!B15 -> 0 | C15: =คะแนนเก็บ!C15 -> 0 | N15: =IFERROR(MAX(_xlfn.MODE.MULT(D15:M15)), "")
A16: =คะแนนเก็บ!A16 -> 12 | B16: =คะแนนเก็บ!B16 -> 0 | C16: =คะแนนเก็บ!C16 -> 0 | N16: =IFERROR(MAX(_xlfn.MODE.MULT(D16:M16)), "")
... A64: =คะแนนเก็บ!A64 -> 60 | B64: =คะแนนเก็บ!B64 -> 0 | C64: =คะแนนเก็บ!C64 -> 0 | N64: =IFERROR(MAX(_xlfn.MODE.MULT(D64:M64)), "")

Sheet สำหรับdev1
A1: fRatioQuiz | B1: fRatioBeforeMidTerm | C1: fRatioAfterMidTerm | D1: fRatioMidTerm | E1: fRatioLateTerm | F1: fRatioQuizPass | G1: maxGrade1 | H1: maxGrade2 | I1: maxGrade3 | J1: maxGrade4 | K1: maxGrade5 | L1: maxGrade6 | M1: maxGrade7 | N1: maxGrade8 | O1: maxGrade9 | P1: maxGrade10 | Q1: maxGrade11 | R1: maxGrade12 | S1: maxGrade13 | T1: maxGrade14 | U1: maxGrade15 | V1: maxGrade16 | W1: maxGrade17 | X1: maxGrade18 | Y1: maxGrade19 | Z1: maxGrade20 | AA1: nameGrade1 | AB1: nameGrade2 | AC1: nameGrade3 | AD1: nameGrade4 | AE1: nameGrade5 | AF1: nameGrade6 | AG1: nameGrade7 | AH1: nameGrade8 | AI1: nameGrade9 | AJ1: nameGrade10 | AK1: nameGrade11 | AL1: nameGrade12 | AM1: nameGrade13 | AN1: nameGrade14 | AO1: nameGrade15 | AP1: nameGrade16 | AQ1: nameGrade17 | AR1: nameGrade18 | AS1: nameGrade19 | AT1: nameGrade20 | AU1: maxCheewat1 | AV1: maxCheewat2 | AW1: maxCheewat3 | AX1: maxCheewat4 | AY1: maxCheewat5 | AZ1: maxCheewat6 | BA1: maxCheewat7 | BB1: maxCheewat8 | BC1: maxCheewat9 | BD1: maxCheewat10 | BE1: maxCheewat11 | BF1: maxCheewat12 | BG1: maxCheewat13 | BH1: maxCheewat14 | BI1: maxCheewat15 | BJ1: maxCheewat16 | BK1: maxCheewat17 | BL1: maxCheewat18 | BM1: maxCheewat19 | BN1: maxCheewat20 | BO1: nameCheewat1 | BP1: nameCheewat2 | BQ1: nameCheewat3 | BR1: nameCheewat4 | BS1: nameCheewat5 | BT1: nameCheewat6 | BU1: nameCheewat7 | BV1: nameCheewat8 | BW1: nameCheewat9 | BX1: nameCheewat10 | BY1: nameCheewat11 | BZ1: nameCheewat12 | CA1: nameCheewat13 | CB1: nameCheewat14 | CC1: nameCheewat15 | CD1: nameCheewat16 | CE1: nameCheewat17 | CF1: nameCheewat18 | CG1: nameCheewat19 | CH1: nameCheewat20 | CI1: maxBehavior1 | CJ1: maxBehavior2 | CK1: maxBehavior3 | CL1: maxBehavior4 | CM1: maxBehavior5 | CN1: maxBehavior6 | CO1: maxBehavior7 | CP1: maxBehavior8 | CQ1: maxBehavior9 | CR1: maxBehavior10 | CS1: nameBehavior1 | CT1: nameBehavior2 | CU1: nameBehavior3 | CV1: nameBehavior4 | CW1: nameBehavior5 | CX1: nameBehavior6 | CY1: nameBehavior7 | CZ1: nameBehavior8 | DA1: nameBehavior9 | DB1: nameBehavior10 | DC1: nameMid1 | DD1: nameMid2 | DE1: nameMid3 | DF1: nameMid4 | DG1: nameMid5 | DH1: nameMid6 | DI1: nameMid7 | DJ1: nameMid8 | DK1: nameMid9 | DL1: nameMid10 | DM1: nameFinal1 | DN1: nameFinal2 | DO1: nameFinal3 | DP1: nameFinal4 | DQ1: nameFinal5 | DR1: nameFinal6 | DS1: nameFinal7 | DT1: nameFinal8 | DU1: nameFinal9 | DV1: nameFinal10 | DW1: maxMid1 | DX1: maxMid2 | DY1: maxMid3 | DZ1: maxMid4 | EA1: maxMid5 | EB1: maxMid6 | EC1: maxMid7 | ED1: maxMid8 | EE1: maxMid9 | EF1: maxMid10 | EG1: maxFinal1 | EH1: maxFinal2 | EI1: maxFinal3 | EJ1: maxFinal4 | EK1: maxFinal5 | EL1: maxFinal6 | EM1: maxFinal7 | EN1: maxFinal8 | EO1: maxFinal9 | EP1: maxFinal10 | EQ1: maxBeforeMidTermTotal | ER1: maxAfterMidTermTotal | ES1: maxgradetotal | ET1: maxmidtotal | EU1: maxfinaltotal | EV1: maxReadWrite1 | EW1: maxReadWrite2 | EX1: maxReadWrite3 | EY1: maxReadWrite4 | EZ1: maxReadWrite5 | FA1: nameReadWrite1 | FB1: nameReadWrite2 | FC1: nameReadWrite3 | FD1: nameReadWrite4 | FE1: nameReadWrite5 | FF1: maxSamattana1 | FG1: maxSamattana2 | FH1: maxSamattana3 | FI1: maxSamattana4 | FJ1: maxSamattana5 | FK1: maxSamattana6 | FL1: maxSamattana7 | FM1: maxSamattana8 | FN1: maxSamattana9 | FO1: maxSamattana10 | FP1: nameSamattana1 | FQ1: nameSamattana2 | FR1: nameSamattana3 | FS1: nameSamattana4 | FT1: nameSamattana5 | FU1: nameSamattana6 | FV1: nameSamattana7 | FW1: nameSamattana8 | FX1: nameSamattana9 | FY1: nameSamattana10 | FZ1: maxBehavior11 | GA1: maxBehavior12 | GB1: maxBehavior13 | GC1: maxBehavior14 | GD1: maxBehavior15 | GE1: maxBehavior16 | GF1: maxBehavior17 | GG1: maxBehavior18 | GH1: maxBehavior19 | GI1: maxBehavior20 | GJ1: nameBehavior11 | GK1: nameBehavior12 | GL1: nameBehavior13 | GM1: nameBehavior14 | GN1: nameBehavior15 | GO1: nameBehavior16 | GP1: nameBehavior17 | GQ1: nameBehavior18 | GR1: nameBehavior19 | GS1: nameBehavior20
A2: =(ตั้งค่าสัดส่วนคะแนน!A3+ตั้งค่าสัดส่วนคะแนน!C3) -> 0 | B2: =ตั้งค่าสัดส่วนคะแนน!A3 -> 0 | C2: =ตั้งค่าสัดส่วนคะแนน!C3 -> 0 | D2: =ตั้งค่าสัดส่วนคะแนน!B3 -> 0 | E2: =ตั้งค่าสัดส่วนคะแนน!D3 -> 0 | F2: =ตั้งค่าสัดส่วนคะแนน!E3 -> 0 | G2: =IF(คะแนนเก็บ!D4=0,"",คะแนนเก็บ!D4) -> 10 | H2: =IF(คะแนนเก็บ!E4=0,"",คะแนนเก็บ!E4) | I2: =IF(คะแนนเก็บ!F4=0,"",คะแนนเก็บ!F4) | J2: =IF(คะแนนเก็บ!G4=0,"",คะแนนเก็บ!G4) | K2: =IF(คะแนนเก็บ!H4=0,"",คะแนนเก็บ!H4) | L2: =IF(คะแนนเก็บ!I4=0,"",คะแนนเก็บ!I4) | M2: =IF(คะแนนเก็บ!J4=0,"",คะแนนเก็บ!J4) | N2: =IF(คะแนนเก็บ!K4=0,"",คะแนนเก็บ!K4) | ... Z2: =IF(คะแนนเก็บ!W4=0,"",คะแนนเก็บ!W4) | AA2: =IF(คะแนนเก็บ!D3=0,"",คะแนนเก็บ!D3) -> ตัวอย่าง | AB2: =IF(คะแนนเก็บ!E3=0,"",คะแนนเก็บ!E3) -> 2 | AC2: =IF(คะแนนเก็บ!F3=0,"",คะแนนเก็บ!F3) -> 3 | AD2: =IF(คะแนนเก็บ!G3=0,"",คะแนนเก็บ!G3) -> 4 | AE2: =IF(คะแนนเก็บ!H3=0,"",คะแนนเก็บ!H3) -> 5 | AF2: =IF(คะแนนเก็บ!I3=0,"",คะแนนเก็บ!I3) -> 6 | AG2: =IF(คะแนนเก็บ!J3=0,"",คะแนนเก็บ!J3) -> 7 | AH2: =IF(คะแนนเก็บ!K3=0,"",คะแนนเก็บ!K3) -> 8 | ... AT2: =IF(คะแนนเก็บ!W3=0,"",คะแนนเก็บ!W3) -> 20 | AU2: =IF(คะแนนเก็บหลังกลางภาค!D4=0,"",คะแนนเก็บหลังกลางภาค!D4) | AV2: =IF(คะแนนเก็บหลังกลางภาค!E4=0,"",คะแนนเก็บหลังกลางภาค!E4) | AW2: =IF(คะแนนเก็บหลังกลางภาค!F4=0,"",คะแนนเก็บหลังกลางภาค!F4) | AX2: =IF(คะแนนเก็บหลังกลางภาค!G4=0,"",คะแนนเก็บหลังกลางภาค!G4) | AY2: =IF(คะแนนเก็บหลังกลางภาค!H4=0,"",คะแนนเก็บหลังกลางภาค!H4) | AZ2: =IF(คะแนนเก็บหลังกลางภาค!I4=0,"",คะแนนเก็บหลังกลางภาค!I4) | BA2: =IF(คะแนนเก็บหลังกลางภาค!J4=0,"",คะแนนเก็บหลังกลางภาค!J4) | BB2: =IF(คะแนนเก็บหลังกลางภาค!K4=0,"",คะแนนเก็บหลังกลางภาค!K4) | ... BN2: =IF(คะแนนเก็บหลังกลางภาค!W4=0,"",คะแนนเก็บหลังกลางภาค!W4) | BO2: =IF(คะแนนเก็บหลังกลางภาค!D3=0,"",คะแนนเก็บหลังกลางภาค!D3) -> 1 | BP2: =IF(คะแนนเก็บหลังกลางภาค!E3=0,"",คะแนนเก็บหลังกลางภาค!E3) -> 2 | BQ2: =IF(คะแนนเก็บหลังกลางภาค!F3=0,"",คะแนนเก็บหลังกลางภาค!F3) -> 3 | BR2: =IF(คะแนนเก็บหลังกลางภาค!G3=0,"",คะแนนเก็บหลังกลางภาค!G3) -> 4 | BS2: =IF(คะแนนเก็บหลังกลางภาค!H3=0,"",คะแนนเก็บหลังกลางภาค!H3) -> 5 | BT2: =IF(คะแนนเก็บหลังกลางภาค!I3=0,"",คะแนนเก็บหลังกลางภาค!I3) -> 6 | BU2: =IF(คะแนนเก็บหลังกลางภาค!J3=0,"",คะแนนเก็บหลังกลางภาค!J3) -> 7 | BV2: =IF(คะแนนเก็บหลังกลางภาค!K3=0,"",คะแนนเก็บหลังกลางภาค!K3) -> 8 | ... CH2: =IF(คะแนนเก็บหลังกลางภาค!W3=0,"",คะแนนเก็บหลังกลางภาค!W3) -> 20 | CI2: =IF(คุณลักษณะอันพึงประสงค์!D4=0,"",คุณลักษณะอันพึงประสงค์!D4) -> 3 | CJ2: =IF(คุณลักษณะอันพึงประสงค์!E4=0,"",คุณลักษณะอันพึงประสงค์!E4) -> 3 | CK2: =IF(คุณลักษณะอันพึงประสงค์!F4=0,"",คุณลักษณะอันพึงประสงค์!F4) -> 3 | CL2: =IF(คุณลักษณะอันพึงประสงค์!G4=0,"",คุณลักษณะอันพึงประสงค์!G4) -> 3 | CM2: =IF(คุณลักษณะอันพึงประสงค์!H4=0,"",คุณลักษณะอันพึงประสงค์!H4) -> 3 | CN2: =IF(คุณลักษณะอันพึงประสงค์!I4=0,"",คุณลักษณะอันพึงประสงค์!I4) -> 3 | CO2: =IF(คุณลักษณะอันพึงประสงค์!J4=0,"",คุณลักษณะอันพึงประสงค์!J4) -> 3 | CP2: =IF(คุณลักษณะอันพึงประสงค์!K4=0,"",คุณลักษณะอันพึงประสงค์!K4) -> 3 | ... CR2: =IF(คุณลักษณะอันพึงประสงค์!M4=0,"",คุณลักษณะอันพึงประสงค์!M4) | CS2: =IF(คุณลักษณะอันพึงประสงค์!D3=0,"",คุณลักษณะอันพึงประสงค์!D3) -> 1 รักชาติ ศาสน์ กษัตริย์ | CT2: =IF(คุณลักษณะอันพึงประสงค์!E3=0,"",คุณลักษณะอันพึงประสงค์!E3) -> 2 ซื่อสัตย์สุจริต | CU2: =IF(คุณลักษณะอันพึงประสงค์!F3=0,"",คุณลักษณะอันพึงประสงค์!F3) -> 3 มีวินัย | CV2: =IF(คุณลักษณะอันพึงประสงค์!G3=0,"",คุณลักษณะอันพึงประสงค์!G3) -> 4 ใฝ่เรียนรู้ | CW2: =IF(คุณลักษณะอันพึงประสงค์!H3=0,"",คุณลักษณะอันพึงประสงค์!H3) -> 5 อยู่อย่างพอเพียง | CX2: =IF(คุณลักษณะอันพึงประสงค์!I3=0,"",คุณลักษณะอันพึงประสงค์!I3) -> 6 มุ่งมั่นในการทำงาน | CY2: =IF(คุณลักษณะอันพึงประสงค์!J3=0,"",คุณลักษณะอันพึงประสงค์!J3) -> 7 รักความเป็นไทย | CZ2: =IF(คุณลักษณะอันพึงประสงค์!K3=0,"",คุณลักษณะอันพึงประสงค์!K3) -> 8 มีจิตสาธารณะ | ... DB2: =IF(คุณลักษณะอันพึงประสงค์!M3=0,"",คุณลักษณะอันพึงประสงค์!M3) -> 10 | DC2: =IF(กลางภาค!D3=0,"",กลางภาค!D3) -> 1 | DD2: =IF(กลางภาค!E3=0,"",กลางภาค!E3) -> 2 | DE2: =IF(กลางภาค!F3=0,"",กลางภาค!F3) -> 3 | DF2: =IF(กลางภาค!G3=0,"",กลางภาค!G3) -> 4 | DG2: =IF(กลางภาค!H3=0,"",กลางภาค!H3) -> 5 | DH2: =IF(กลางภาค!I3=0,"",กลางภาค!I3) -> 6 | DI2: =IF(กลางภาค!J3=0,"",กลางภาค!J3) -> 7 | DJ2: =IF(กลางภาค!K3=0,"",กลางภาค!K3) -> 8 | ... DL2: =IF(กลางภาค!M3=0,"",กลางภาค!M3) -> 10 | DM2: =IF(ปลายภาค!D3=0,"",ปลายภาค!D3) -> 1 | DN2: =IF(ปลายภาค!E3=0,"",ปลายภาค!E3) -> 2 | DO2: =IF(ปลายภาค!F3=0,"",ปลายภาค!F3) -> 3 | DP2: =IF(ปลายภาค!G3=0,"",ปลายภาค!G3) -> 4 | DQ2: =IF(ปลายภาค!H3=0,"",ปลายภาค!H3) -> 5 | DR2: =IF(ปลายภาค!I3=0,"",ปลายภาค!I3) -> 6 | DS2: =IF(ปลายภาค!J3=0,"",ปลายภาค!J3) -> 7 | DT2: =IF(ปลายภาค!K3=0,"",ปลายภาค!K3) -> 8 | ... DV2: =IF(ปลายภาค!M3=0,"",ปลายภาค!M3) -> 10 | DW2: =IF(กลางภาค!D4=0,"",กลางภาค!D4) | DX2: =IF(กลางภาค!E4=0,"",กลางภาค!E4) | DY2: =IF(กลางภาค!F4=0,"",กลางภาค!F4) | DZ2: =IF(กลางภาค!G4=0,"",กลางภาค!G4) | EA2: =IF(กลางภาค!H4=0,"",กลางภาค!H4) | EB2: =IF(กลางภาค!I4=0,"",กลางภาค!I4) | EC2: =IF(กลางภาค!J4=0,"",กลางภาค!J4) | ED2: =IF(กลางภาค!K4=0,"",กลางภาค!K4) | ... EF2: =IF(กลางภาค!M4=0,"",กลางภาค!M4) | EG2: =IF(ปลายภาค!D4=0,"",ปลายภาค!D4) | EH2: =IF(ปลายภาค!E4=0,"",ปลายภาค!E4) | EI2: =IF(ปลายภาค!F4=0,"",ปลายภาค!F4) | EJ2: =IF(ปลายภาค!G4=0,"",ปลายภาค!G4) | EK2: =IF(ปลายภาค!H4=0,"",ปลายภาค!H4) | EL2: =IF(ปลายภาค!I4=0,"",ปลายภาค!I4) | EM2: =IF(ปลายภาค!J4=0,"",ปลายภาค!J4) | EN2: =IF(ปลายภาค!K4=0,"",ปลายภาค!K4) | ... EP2: =IF(ปลายภาค!M4=0,"",ปลายภาค!M4) | EQ2: =IF(คะแนนเก็บ!X4=0,"",คะแนนเก็บ!X4) -> 10 | ER2: =IF(คะแนนเก็บหลังกลางภาค!X4=0,"",คะแนนเก็บหลังกลางภาค!X4) | ES2: =SUM(คะแนนเก็บ!X4+คะแนนเก็บหลังกลางภาค!X4) -> #VALUE! | ET2: =IF(กลางภาค!N4=0,"",กลางภาค!N4) | EU2: =IF(ปลายภาค!N4=0,"",ปลายภาค!N4) | EV2: =IF(อ่านคิดวิเคราะห์!D4=0,"",อ่านคิดวิเคราะห์!D4) -> 3 | EW2: =IF(อ่านคิดวิเคราะห์!E4=0,"",อ่านคิดวิเคราะห์!E4) -> 3 | EX2: =IF(อ่านคิดวิเคราะห์!F4=0,"",อ่านคิดวิเคราะห์!F4) -> 3 | EY2: =IF(อ่านคิดวิเคราะห์!G4=0,"",อ่านคิดวิเคราะห์!G4) | EZ2: =IF(อ่านคิดวิเคราะห์!H4=0,"",อ่านคิดวิเคราะห์!H4) | FA2: =IF(อ่านคิดวิเคราะห์!D3=0,"",อ่านคิดวิเคราะห์!D3) -> 1 การอ่าน | FB2: =IF(อ่านคิดวิเคราะห์!E3=0,"",อ่านคิดวิเคราะห์!E3) -> 2 การคิดวิเคราะห์ | FC2: =IF(อ่านคิดวิเคราะห์!F3=0,"",อ่านคิดวิเคราะห์!F3) -> 3 การเขียน | FD2: =IF(อ่านคิดวิเคราะห์!G3=0,"",อ่านคิดวิเคราะห์!G3) | FE2: =IF(อ่านคิดวิเคราะห์!H3=0,"",อ่านคิดวิเคราะห์!H3) | FF2: =IF(สมรรถนะ!D4=0,"",สมรรถนะ!D4) -> 3 | FG2: =IF(สมรรถนะ!E4=0,"",สมรรถนะ!E4) -> 3 | FH2: =IF(สมรรถนะ!F4=0,"",สมรรถนะ!F4) -> 3 | FI2: =IF(สมรรถนะ!G4=0,"",สมรรถนะ!G4) -> 3 | FJ2: =IF(สมรรถนะ!H4=0,"",สมรรถนะ!H4) -> 3 | FK2: =IF(สมรรถนะ!I4=0,"",สมรรถนะ!I4) | FL2: =IF(สมรรถนะ!J4=0,"",สมรรถนะ!J4) | FM2: =IF(สมรรถนะ!K4=0,"",สมรรถนะ!K4) | ... FO2: =IF(สมรรถนะ!M4=0,"",สมรรถนะ!M4) | FP2: =IF(สมรรถนะ!D3=0,"",สมรรถนะ!D3) -> 1 หัวข้อตามที่ตั้งค่าในระบบ | FQ2: =IF(สมรรถนะ!E3=0,"",สมรรถนะ!E3) -> 2 หัวข้อตามที่ตั้งค่าในระบบ | FR2: =IF(สมรรถนะ!F3=0,"",สมรรถนะ!F3) -> 3 หัวข้อตามที่ตั้งค่าในระบบ | FS2: =IF(สมรรถนะ!G3=0,"",สมรรถนะ!G3) -> 4 หัวข้อตามที่ตั้งค่าในระบบ | FT2: =IF(สมรรถนะ!H3=0,"",สมรรถนะ!H3) -> 5 หัวข้อตามที่ตั้งค่าในระบบ | FU2: =IF(สมรรถนะ!I3=0,"",สมรรถนะ!I3) -> 6 หัวข้อตามที่ตั้งค่าในระบบ | FV2: =IF(สมรรถนะ!J3=0,"",สมรรถนะ!J3) -> 7 หัวข้อตามที่ตั้งค่าในระบบ | FW2: =IF(สมรรถนะ!K3=0,"",สมรรถนะ!K3) -> 8 หัวข้อตามที่ตั้งค่าในระบบ | ... FY2: =IF(สมรรถนะ!M3=0,"",สมรรถนะ!M3) -> 10 หัวข้อตามที่ตั้งค่าในระบบ | FZ2: =IF(คุณลักษณะอันพึงประสงค์!N4=0,"",คุณลักษณะอันพึงประสงค์!N4) | GA2: =IF(คุณลักษณะอันพึงประสงค์!O4=0,"",คุณลักษณะอันพึงประสงค์!O4) | GB2: =IF(คุณลักษณะอันพึงประสงค์!P4=0,"",คุณลักษณะอันพึงประสงค์!P4) | GC2: =IF(คุณลักษณะอันพึงประสงค์!Q4=0,"",คุณลักษณะอันพึงประสงค์!Q4) | GD2: =IF(คุณลักษณะอันพึงประสงค์!R4=0,"",คุณลักษณะอันพึงประสงค์!R4) | GE2: =IF(คุณลักษณะอันพึงประสงค์!S4=0,"",คุณลักษณะอันพึงประสงค์!S4) | GF2: =IF(คุณลักษณะอันพึงประสงค์!T4=0,"",คุณลักษณะอันพึงประสงค์!T4) | GG2: =IF(คุณลักษณะอันพึงประสงค์!U4=0,"",คุณลักษณะอันพึงประสงค์!U4) | ... GI2: =IF(คุณลักษณะอันพึงประสงค์!W4=0,"",คุณลักษณะอันพึงประสงค์!W4) | GJ2: =IF(คุณลักษณะอันพึงประสงค์!N3=0,"",คุณลักษณะอันพึงประสงค์!N3) -> 11 | GK2: =IF(คุณลักษณะอันพึงประสงค์!O3=0,"",คุณลักษณะอันพึงประสงค์!O3) -> 12 | GL2: =IF(คุณลักษณะอันพึงประสงค์!P3=0,"",คุณลักษณะอันพึงประสงค์!P3) -> 13 | GM2: =IF(คุณลักษณะอันพึงประสงค์!Q3=0,"",คุณลักษณะอันพึงประสงค์!Q3) -> 14 | GN2: =IF(คุณลักษณะอันพึงประสงค์!R3=0,"",คุณลักษณะอันพึงประสงค์!R3) -> 15 | GO2: =IF(คุณลักษณะอันพึงประสงค์!S3=0,"",คุณลักษณะอันพึงประสงค์!S3) -> 16 | GP2: =IF(คุณลักษณะอันพึงประสงค์!T3=0,"",คุณลักษณะอันพึงประสงค์!T3) -> 17 | GQ2: =IF(คุณลักษณะอันพึงประสงค์!U3=0,"",คุณลักษณะอันพึงประสงค์!U3) -> 18 | ... GS2: =IF(คุณลักษณะอันพึงประสงค์!W3=0,"",คุณลักษณะอันพึงประสงค์!W3) -> 20

Sheet สำหรับdev2
A1: stdSID | B1: scoreGrade1 | C1: scoreGrade2 | D1: scoreGrade3 | E1: scoreGrade4 | F1: scoreGrade5 | G1: scoreGrade6 | H1: scoreGrade7 | I1: scoreGrade8 | J1: scoreGrade9 | K1: scoreGrade10 | L1: scoreGrade11 | M1: scoreGrade12 | N1: scoreGrade13 | O1: scoreGrade14 | P1: scoreGrade15 | Q1: scoreGrade16 | R1: scoreGrade17 | S1: scoreGrade18 | T1: scoreGrade19 | U1: scoreGrade20 | V1: scoreCheewat1 | W1: scoreCheewat2 | X1: scoreCheewat3 | Y1: scoreCheewat4 | Z1: scoreCheewat5 | AA1: scoreCheewat6 | AB1: scoreCheewat7 | AC1: scoreCheewat8 | AD1: scoreCheewat9 | AE1: scoreCheewat10 | AF1: scoreCheewat11 | AG1: scoreCheewat12 | AH1: scoreCheewat13 | AI1: scoreCheewat14 | AJ1: scoreCheewat15 | AK1: scoreCheewat16 | AL1: scoreCheewat17 | AM1: scoreCheewat18 | AN1: scoreCheewat19 | AO1: scoreCheewat20 | AP1: scoreBehavior1 | AQ1: scoreBehavior2 | AR1: scoreBehavior3 | AS1: scoreBehavior4 | AT1: scoreBehavior5 | AU1: scoreBehavior6 | AV1: scoreBehavior7 | AW1: scoreBehavior8 | AX1: scoreBehavior9 | AY1: scoreBehavior10 | AZ1: scoreMid1 | BA1: scoreMid2 | BB1: scoreMid3 | BC1: scoreMid4 | BD1: scoreMid5 | BE1: scoreMid6 | BF1: scoreMid7 | BG1: scoreMid8 | BH1: scoreMid9 | BI1: scoreMid10 | BJ1: scoreFinal1 | BK1: scoreFinal2 | BL1: scoreFinal3 | BM1: scoreFinal4 | BN1: scoreFinal5 | BO1: scoreFinal6 | BP1: scoreFinal7 | BQ1: scoreFinal8 | BR1: scoreFinal9 | BS1: scoreFinal10 | BT1: scoreMidTermSUM | BU1: scoreFinalTermSUM | BV1: scoreBahaviorSUM | BW1: getReadWrite | BX1: scoreSamatana | BY1: scoreReadWrite1 | BZ1: scoreReadWrite2 | CA1: scoreReadWrite3 | CB1: scoreReadWrite4 | CC1: scoreReadWrite5 | CD1: scoreSamattana1 | CE1: scoreSamattana2 | CF1: scoreSamattana3 | CG1: scoreSamattana4 | CH1: scoreSamattana5 | CI1: scoreSamattana6 | CJ1: scoreSamattana7 | CK1: scoreSamattana8 | CL1: scoreSamattana9 | CM1: scoreSamattana10 | CN1: scoreBehavior11 | CO1: scoreBehavior12 | CP1: scoreBehavior13 | CQ1: scoreBehavior14 | CR1: scoreBehavior15 | CS1: scoreBehavior16 | CT1: scoreBehavior17 | CU1: scoreBehavior18 | CV1: scoreBehavior19 | CW1: scoreBehavior20
A2: =IF(คะแนนเก็บ!B5="","",คะแนนเก็บ!B5) -> 123 | B2: =IF(คะแนนเก็บ!D5="","",คะแนนเก็บ!D5) -> 1 | C2: =IF(คะแนนเก็บ!E5="","",คะแนนเก็บ!E5) | D2: =IF(คะแนนเก็บ!F5="","",คะแนนเก็บ!F5) | E2: =IF(คะแนนเก็บ!G5="","",คะแนนเก็บ!G5) | F2: =IF(คะแนนเก็บ!H5="","",คะแนนเก็บ!H5) | G2: =IF(คะแนนเก็บ!I5="","",คะแนนเก็บ!I5) | H2: =IF(คะแนนเก็บ!J5="","",คะแนนเก็บ!J5) | I2: =IF(คะแนนเก็บ!K5="","",คะแนนเก็บ!K5) | ... U2: =IF(คะแนนเก็บ!W5="","",คะแนนเก็บ!W5) | V2: =IF(คะแนนเก็บหลังกลางภาค!D5="","",คะแนนเก็บหลังกลางภาค!D5) | W2: =IF(คะแนนเก็บหลังกลางภาค!E5="","",คะแนนเก็บหลังกลางภาค!E5) | X2: =IF(คะแนนเก็บหลังกลางภาค!F5="","",คะแนนเก็บหลังกลางภาค!F5) | Y2: =IF(คะแนนเก็บหลังกลางภาค!G5="","",คะแนนเก็บหลังกลางภาค!G5) | Z2: =IF(คะแนนเก็บหลังกลางภาค!H5="","",คะแนนเก็บหลังกลางภาค!H5) | AA2: =IF(คะแนนเก็บหลังกลางภาค!I5="","",คะแนนเก็บหลังกลางภาค!I5) | AB2: =IF(คะแนนเก็บหลังกลางภาค!J5="","",คะแนนเก็บหลังกลางภาค!J5) | AC2: =IF(คะแนนเก็บหลังกลางภาค!K5="","",คะแนนเก็บหลังกลางภาค!K5) | ... AO2: =IF(คะแนนเก็บหลังกลางภาค!W5="","",คะแนนเก็บหลังกลางภาค!W5) | AP2: =IF(คุณลักษณะอันพึงประสงค์!D5="","",คุณลักษณะอันพึงประสงค์!D5) | AQ2: =IF(คุณลักษณะอันพึงประสงค์!E5="","",คุณลักษณะอันพึงประสงค์!E5) | AR2: =IF(คุณลักษณะอันพึงประสงค์!F5="","",คุณลักษณะอันพึงประสงค์!F5) | AS2: =IF(คุณลักษณะอันพึงประสงค์!G5="","",คุณลักษณะอันพึงประสงค์!G5) | AT2: =IF(คุณลักษณะอันพึงประสงค์!H5="","",คุณลักษณะอันพึงประสงค์!H5) | AU2: =IF(คุณลักษณะอันพึงประสงค์!I5="","",คุณลักษณะอันพึงประสงค์!I5) | AV2: =IF(คุณลักษณะอันพึงประสงค์!J5="","",คุณลักษณะอันพึงประสงค์!J5) | AW2: =IF(คุณลักษณะอันพึงประสงค์!K5="","",คุณลักษณะอันพึงประสงค์!K5) | ... AY2: =IF(คุณลักษณะอันพึงประสงค์!M5="","",คุณลักษณะอันพึงประสงค์!M5) | AZ2: =IF(กลางภาค!D5="","",กลางภาค!D5) | BA2: =IF(กลางภาค!E5="","",กลางภาค!E5) | BB2: =IF(กลางภาค!F5="","",กลางภาค!F5) | BC2: =IF(กลางภาค!G5="","",กลางภาค!G5) | BD2: =IF(กลางภาค!H5="","",กลางภาค!H5) | BE2: =IF(กลางภาค!I5="","",กลางภาค!I5) | BF2: =IF(กลางภาค!J5="","",กลางภาค!J5) | BG2: =IF(กลางภาค!K5="","",กลางภาค!K5) | ... BI2: =IF(กลางภาค!M5="","",กลางภาค!M5) | BJ2: =IF(ปลายภาค!D5="","",ปลายภาค!D5) | BK2: =IF(ปลายภาค!E5="","",ปลายภาค!E5) | BL2: =IF(ปลายภาค!F5="","",ปลายภาค!F5) | BM2: =IF(ปลายภาค!G5="","",ปลายภาค!G5) | BN2: =IF(ปลายภาค!H5="","",ปลายภาค!H5) | BO2: =IF(ปลายภาค!I5="","",ปลายภาค!I5) | BP2: =IF(ปลายภาค!J5="","",ปลายภาค!J5) | BQ2: =IF(ปลายภาค!K5="","",ปลายภาค!K5) | ... BS2: =IF(ปลายภาค!M5="","",ปลายภาค!M5) | BT2: =IF(กลางภาค!N5="","",กลางภาค!N5) | BU2: =IF(ปลายภาค!N5="","",ปลายภาค!N5) | BV2: =IF(คุณลักษณะอันพึงประสงค์!X5="","",คุณลักษณะอันพึงประสงค์!X5) | BW2: =IF(อ่านคิดวิเคราะห์!I5="","",อ่านคิดวิเคราะห์!I5) | BX2: =IF(สมรรถนะ!N5="","",สมรรถนะ!N5) | BY2: =IF(อ่านคิดวิเคราะห์!D5="","",อ่านคิดวิเคราะห์!D5) | BZ2: =IF(อ่านคิดวิเคราะห์!E5="","",อ่านคิดวิเคราะห์!E5) | CA2: =IF(อ่านคิดวิเคราะห์!F5="","",อ่านคิดวิเคราะห์!F5) | CB2: =IF(อ่านคิดวิเคราะห์!G5="","",อ่านคิดวิเคราะห์!G5) | CC2: =IF(อ่านคิดวิเคราะห์!H5="","",อ่านคิดวิเคราะห์!H5) | CD2: =IF(สมรรถนะ!D5="","",สมรรถนะ!D5) | CE2: =IF(สมรรถนะ!E5="","",สมรรถนะ!E5) | CF2: =IF(สมรรถนะ!F5="","",สมรรถนะ!F5) | CG2: =IF(สมรรถนะ!G5="","",สมรรถนะ!G5) | CH2: =IF(สมรรถนะ!H5="","",สมรรถนะ!H5) | CI2: =IF(สมรรถนะ!I5="","",สมรรถนะ!I5) | CJ2: =IF(สมรรถนะ!J5="","",สมรรถนะ!J5) | CK2: =IF(สมรรถนะ!K5="","",สมรรถนะ!K5) | ... CM2: =IF(สมรรถนะ!M5="","",สมรรถนะ!M5) | CN2: =IF(คุณลักษณะอันพึงประสงค์!N5="","",คุณลักษณะอันพึงประสงค์!N5) | CO2: =IF(คุณลักษณะอันพึงประสงค์!O5="","",คุณลักษณะอันพึงประสงค์!O5) | CP2: =IF(คุณลักษณะอันพึงประสงค์!P5="","",คุณลักษณะอันพึงประสงค์!P5) | CQ2: =IF(คุณลักษณะอันพึงประสงค์!Q5="","",คุณลักษณะอันพึงประสงค์!Q5) | CR2: =IF(คุณลักษณะอันพึงประสงค์!R5="","",คุณลักษณะอันพึงประสงค์!R5) | CS2: =IF(คุณลักษณะอันพึงประสงค์!S5="","",คุณลักษณะอันพึงประสงค์!S5) | CT2: =IF(คุณลักษณะอันพึงประสงค์!T5="","",คุณลักษณะอันพึงประสงค์!T5) | CU2: =IF(คุณลักษณะอันพึงประสงค์!U5="","",คุณลักษณะอันพึงประสงค์!U5) | ... CW2: =IF(คุณลักษณะอันพึงประสงค์!W5="","",คุณลักษณะอันพึงประสงค์!W5)
A3: =IF(คะแนนเก็บ!B6="","",คะแนนเก็บ!B6) -> 456 | B3: =IF(คะแนนเก็บ!D6="","",คะแนนเก็บ!D6) -> 2 | C3: =IF(คะแนนเก็บ!E6="","",คะแนนเก็บ!E6) | D3: =IF(คะแนนเก็บ!F6="","",คะแนนเก็บ!F6) | E3: =IF(คะแนนเก็บ!G6="","",คะแนนเก็บ!G6) | F3: =IF(คะแนนเก็บ!H6="","",คะแนนเก็บ!H6) | G3: =IF(คะแนนเก็บ!I6="","",คะแนนเก็บ!I6) | H3: =IF(คะแนนเก็บ!J6="","",คะแนนเก็บ!J6) | I3: =IF(คะแนนเก็บ!K6="","",คะแนนเก็บ!K6) | ... U3: =IF(คะแนนเก็บ!W6="","",คะแนนเก็บ!W6) | V3: =IF(คะแนนเก็บหลังกลางภาค!D6="","",คะแนนเก็บหลังกลางภาค!D6) | W3: =IF(คะแนนเก็บหลังกลางภาค!E6="","",คะแนนเก็บหลังกลางภาค!E6) | X3: =IF(คะแนนเก็บหลังกลางภาค!F6="","",คะแนนเก็บหลังกลางภาค!F6) | Y3: =IF(คะแนนเก็บหลังกลางภาค!G6="","",คะแนนเก็บหลังกลางภาค!G6) | Z3: =IF(คะแนนเก็บหลังกลางภาค!H6="","",คะแนนเก็บหลังกลางภาค!H6) | AA3: =IF(คะแนนเก็บหลังกลางภาค!I6="","",คะแนนเก็บหลังกลางภาค!I6) | AB3: =IF(คะแนนเก็บหลังกลางภาค!J6="","",คะแนนเก็บหลังกลางภาค!J6) | AC3: =IF(คะแนนเก็บหลังกลางภาค!K6="","",คะแนนเก็บหลังกลางภาค!K6) | ... AO3: =IF(คะแนนเก็บหลังกลางภาค!W6="","",คะแนนเก็บหลังกลางภาค!W6) | AP3: =IF(คุณลักษณะอันพึงประสงค์!D6="","",คุณลักษณะอันพึงประสงค์!D6) | AQ3: =IF(คุณลักษณะอันพึงประสงค์!E6="","",คุณลักษณะอันพึงประสงค์!E6) | AR3: =IF(คุณลักษณะอันพึงประสงค์!F6="","",คุณลักษณะอันพึงประสงค์!F6) | AS3: =IF(คุณลักษณะอันพึงประสงค์!G6="","",คุณลักษณะอันพึงประสงค์!G6) | AT3: =IF(คุณลักษณะอันพึงประสงค์!H6="","",คุณลักษณะอันพึงประสงค์!H6) | AU3: =IF(คุณลักษณะอันพึงประสงค์!I6="","",คุณลักษณะอันพึงประสงค์!I6) | AV3: =IF(คุณลักษณะอันพึงประสงค์!J6="","",คุณลักษณะอันพึงประสงค์!J6) | AW3: =IF(คุณลักษณะอันพึงประสงค์!K6="","",คุณลักษณะอันพึงประสงค์!K6) | ... AY3: =IF(คุณลักษณะอันพึงประสงค์!M6="","",คุณลักษณะอันพึงประสงค์!M6) | AZ3: =IF(กลางภาค!D6="","",กลางภาค!D6) | BA3: =IF(กลางภาค!E6="","",กลางภาค!E6) | BB3: =IF(กลางภาค!F6="","",กลางภาค!F6) | BC3: =IF(กลางภาค!G6="","",กลางภาค!G6) | BD3: =IF(กลางภาค!H6="","",กลางภาค!H6) | BE3: =IF(กลางภาค!I6="","",กลางภาค!I6) | BF3: =IF(กลางภาค!J6="","",กลางภาค!J6) | BG3: =IF(กลางภาค!K6="","",กลางภาค!K6) | ... BI3: =IF(กลางภาค!M6="","",กลางภาค!M6) | BJ3: =IF(ปลายภาค!D6="","",ปลายภาค!D6) | BK3: =IF(ปลายภาค!E6="","",ปลายภาค!E6) | BL3: =IF(ปลายภาค!F6="","",ปลายภาค!F6) | BM3: =IF(ปลายภาค!G6="","",ปลายภาค!G6) | BN3: =IF(ปลายภาค!H6="","",ปลายภาค!H6) | BO3: =IF(ปลายภาค!I6="","",ปลายภาค!I6) | BP3: =IF(ปลายภาค!J6="","",ปลายภาค!J6) | BQ3: =IF(ปลายภาค!K6="","",ปลายภาค!K6) | ... BS3: =IF(ปลายภาค!M6="","",ปลายภาค!M6) | BT3: =IF(กลางภาค!N6="","",กลางภาค!N6) | BU3: =IF(ปลายภาค!N6="","",ปลายภาค!N6) | BV3: =IF(คุณลักษณะอันพึงประสงค์!X6="","",คุณลักษณะอันพึงประสงค์!X6) | BW3: =IF(อ่านคิดวิเคราะห์!I6="","",อ่านคิดวิเคราะห์!I6) | BX3: =IF(สมรรถนะ!N6="","",สมรรถนะ!N6) | BY3: =IF(อ่านคิดวิเคราะห์!D6="","",อ่านคิดวิเคราะห์!D6) | BZ3: =IF(อ่านคิดวิเคราะห์!E6="","",อ่านคิดวิเคราะห์!E6) | CA3: =IF(อ่านคิดวิเคราะห์!F6="","",อ่านคิดวิเคราะห์!F6) | CB3: =IF(อ่านคิดวิเคราะห์!G6="","",อ่านคิดวิเคราะห์!G6) | CC3: =IF(อ่านคิดวิเคราะห์!H6="","",อ่านคิดวิเคราะห์!H6) | CD3: =IF(สมรรถนะ!D6="","",สมรรถนะ!D6) | CE3: =IF(สมรรถนะ!E6="","",สมรรถนะ!E6) | CF3: =IF(สมรรถนะ!F6="","",สมรรถนะ!F6) | CG3: =IF(สมรรถนะ!G6="","",สมรรถนะ!G6) | CH3: =IF(สมรรถนะ!H6="","",สมรรถนะ!H6) | CI3: =IF(สมรรถนะ!I6="","",สมรรถนะ!I6) | CJ3: =IF(สมรรถนะ!J6="","",สมรรถนะ!J6) | CK3: =IF(สมรรถนะ!K6="","",สมรรถนะ!K6) | ... CM3: =IF(สมรรถนะ!M6="","",สมรรถนะ!M6) | CN3: =IF(คุณลักษณะอันพึงประสงค์!N6="","",คุณลักษณะอันพึงประสงค์!N6) | CO3: =IF(คุณลักษณะอันพึงประสงค์!O6="","",คุณลักษณะอันพึงประสงค์!O6) | CP3: =IF(คุณลักษณะอันพึงประสงค์!P6="","",คุณลักษณะอันพึงประสงค์!P6) | CQ3: =IF(คุณลักษณะอันพึงประสงค์!Q6="","",คุณลักษณะอันพึงประสงค์!Q6) | CR3: =IF(คุณลักษณะอันพึงประสงค์!R6="","",คุณลักษณะอันพึงประสงค์!R6) | CS3: =IF(คุณลักษณะอันพึงประสงค์!S6="","",คุณลักษณะอันพึงประสงค์!S6) | CT3: =IF(คุณลักษณะอันพึงประสงค์!T6="","",คุณลักษณะอันพึงประสงค์!T6) | CU3: =IF(คุณลักษณะอันพึงประสงค์!U6="","",คุณลักษณะอันพึงประสงค์!U6) | ... CW3: =IF(คุณลักษณะอันพึงประสงค์!W6="","",คุณลักษณะอันพึงประสงค์!W6)
A4: =IF(คะแนนเก็บ!B7="","",คะแนนเก็บ!B7) -> A123 | B4: =IF(คะแนนเก็บ!D7="","",คะแนนเก็บ!D7) -> 3 | C4: =IF(คะแนนเก็บ!E7="","",คะแนนเก็บ!E7) | D4: =IF(คะแนนเก็บ!F7="","",คะแนนเก็บ!F7) | E4: =IF(คะแนนเก็บ!G7="","",คะแนนเก็บ!G7) | F4: =IF(คะแนนเก็บ!H7="","",คะแนนเก็บ!H7) | G4: =IF(คะแนนเก็บ!I7="","",คะแนนเก็บ!I7) | H4: =IF(คะแนนเก็บ!J7="","",คะแนนเก็บ!J7) | I4: =IF(คะแนนเก็บ!K7="","",คะแนนเก็บ!K7) | ... U4: =IF(คะแนนเก็บ!W7="","",คะแนนเก็บ!W7) | V4: =IF(คะแนนเก็บหลังกลางภาค!D7="","",คะแนนเก็บหลังกลางภาค!D7) | W4: =IF(คะแนนเก็บหลังกลางภาค!E7="","",คะแนนเก็บหลังกลางภาค!E7) | X4: =IF(คะแนนเก็บหลังกลางภาค!F7="","",คะแนนเก็บหลังกลางภาค!F7) | Y4: =IF(คะแนนเก็บหลังกลางภาค!G7="","",คะแนนเก็บหลังกลางภาค!G7) | Z4: =IF(คะแนนเก็บหลังกลางภาค!H7="","",คะแนนเก็บหลังกลางภาค!H7) | AA4: =IF(คะแนนเก็บหลังกลางภาค!I7="","",คะแนนเก็บหลังกลางภาค!I7) | AB4: =IF(คะแนนเก็บหลังกลางภาค!J7="","",คะแนนเก็บหลังกลางภาค!J7) | AC4: =IF(คะแนนเก็บหลังกลางภาค!K7="","",คะแนนเก็บหลังกลางภาค!K7) | ... AO4: =IF(คะแนนเก็บหลังกลางภาค!W7="","",คะแนนเก็บหลังกลางภาค!W7) | AP4: =IF(คุณลักษณะอันพึงประสงค์!D7="","",คุณลักษณะอันพึงประสงค์!D7) | AQ4: =IF(คุณลักษณะอันพึงประสงค์!E7="","",คุณลักษณะอันพึงประสงค์!E7) | AR4: =IF(คุณลักษณะอันพึงประสงค์!F7="","",คุณลักษณะอันพึงประสงค์!F7) | AS4: =IF(คุณลักษณะอันพึงประสงค์!G7="","",คุณลักษณะอันพึงประสงค์!G7) | AT4: =IF(คุณลักษณะอันพึงประสงค์!H7="","",คุณลักษณะอันพึงประสงค์!H7) | AU4: =IF(คุณลักษณะอันพึงประสงค์!I7="","",คุณลักษณะอันพึงประสงค์!I7) | AV4: =IF(คุณลักษณะอันพึงประสงค์!J7="","",คุณลักษณะอันพึงประสงค์!J7) | AW4: =IF(คุณลักษณะอันพึงประสงค์!K7="","",คุณลักษณะอันพึงประสงค์!K7) | ... AY4: =IF(คุณลักษณะอันพึงประสงค์!M7="","",คุณลักษณะอันพึงประสงค์!M7) | AZ4: =IF(กลางภาค!D7="","",กลางภาค!D7) | BA4: =IF(กลางภาค!E7="","",กลางภาค!E7) | BB4: =IF(กลางภาค!F7="","",กลางภาค!F7) | BC4: =IF(กลางภาค!G7="","",กลางภาค!G7) | BD4: =IF(กลางภาค!H7="","",กลางภาค!H7) | BE4: =IF(กลางภาค!I7="","",กลางภาค!I7) | BF4: =IF(กลางภาค!J7="","",กลางภาค!J7) | BG4: =IF(กลางภาค!K7="","",กลางภาค!K7) | ... BI4: =IF(กลางภาค!M7="","",กลางภาค!M7) | BJ4: =IF(ปลายภาค!D7="","",ปลายภาค!D7) | BK4: =IF(ปลายภาค!E7="","",ปลายภาค!E7) | BL4: =IF(ปลายภาค!F7="","",ปลายภาค!F7) | BM4: =IF(ปลายภาค!G7="","",ปลายภาค!G7) | BN4: =IF(ปลายภาค!H7="","",ปลายภาค!H7) | BO4: =IF(ปลายภาค!I7="","",ปลายภาค!I7) | BP4: =IF(ปลายภาค!J7="","",ปลายภาค!J7) | BQ4: =IF(ปลายภาค!K7="","",ปลายภาค!K7) | ... BS4: =IF(ปลายภาค!M7="","",ปลายภาค!M7) | BT4: =IF(กลางภาค!N7="","",กลางภาค!N7) | BU4: =IF(ปลายภาค!N7="","",ปลายภาค!N7) | BV4: =IF(คุณลักษณะอันพึงประสงค์!X7="","",คุณลักษณะอันพึงประสงค์!X7) | BW4: =IF(อ่านคิดวิเคราะห์!I7="","",อ่านคิดวิเคราะห์!I7) | BX4: =IF(สมรรถนะ!N7="","",สมรรถนะ!N7) | BY4: =IF(อ่านคิดวิเคราะห์!D7="","",อ่านคิดวิเคราะห์!D7) | BZ4: =IF(อ่านคิดวิเคราะห์!E7="","",อ่านคิดวิเคราะห์!E7) | CA4: =IF(อ่านคิดวิเคราะห์!F7="","",อ่านคิดวิเคราะห์!F7) | CB4: =IF(อ่านคิดวิเคราะห์!G7="","",อ่านคิดวิเคราะห์!G7) | CC4: =IF(อ่านคิดวิเคราะห์!H7="","",อ่านคิดวิเคราะห์!H7) | CD4: =IF(สมรรถนะ!D7="","",สมรรถนะ!D7) | CE4: =IF(สมรรถนะ!E7="","",สมรรถนะ!E7) | CF4: =IF(สมรรถนะ!F7="","",สมรรถนะ!F7) | CG4: =IF(สมรรถนะ!G7="","",สมรรถนะ!G7) | CH4: =IF(สมรรถนะ!H7="","",สมรรถนะ!H7) | CI4: =IF(สมรรถนะ!I7="","",สมรรถนะ!I7) | CJ4: =IF(สมรรถนะ!J7="","",สมรรถนะ!J7) | CK4: =IF(สมรรถนะ!K7="","",สมรรถนะ!K7) | ... CM4: =IF(สมรรถนะ!M7="","",สมรรถนะ!M7) | CN4: =IF(คุณลักษณะอันพึงประสงค์!N7="","",คุณลักษณะอันพึงประสงค์!N7) | CO4: =IF(คุณลักษณะอันพึงประสงค์!O7="","",คุณลักษณะอันพึงประสงค์!O7) | CP4: =IF(คุณลักษณะอันพึงประสงค์!P7="","",คุณลักษณะอันพึงประสงค์!P7) | CQ4: =IF(คุณลักษณะอันพึงประสงค์!Q7="","",คุณลักษณะอันพึงประสงค์!Q7) | CR4: =IF(คุณลักษณะอันพึงประสงค์!R7="","",คุณลักษณะอันพึงประสงค์!R7) | CS4: =IF(คุณลักษณะอันพึงประสงค์!S7="","",คุณลักษณะอันพึงประสงค์!S7) | CT4: =IF(คุณลักษณะอันพึงประสงค์!T7="","",คุณลักษณะอันพึงประสงค์!T7) | CU4: =IF(คุณลักษณะอันพึงประสงค์!U7="","",คุณลักษณะอันพึงประสงค์!U7) | ... CW4: =IF(คุณลักษณะอันพึงประสงค์!W7="","",คุณลักษณะอันพึงประสงค์!W7)
